Workbook
Name Actividade: '[1]Listas para formulário'!$G$2:$G$9
Name Ambito: [2]Tabelas!$AG$1:$AG$5
Name Bolsas_de_Iniciação_Científica__BIC: 'Valores bolsas e 57_2016'!$A$1:$B$9
Name Classificação_das_despesas: '[1]Listas para formulário'!$A$2:$A$15
Name Estabelecimento: '[1]Listas para formulário'!$E$2:$E$4
Name GeneroList: [3]dados_aux!$B$42:$B$45
Name lista: 'Valores bolsas e 57_2016'!$A$1:$A$9
Name Lista2: 'Valores bolsas e 57_2016'!#REF!
Name Lista2: 'Valores bolsas e 57_2016'!#REF!
Name Lista2: 'Valores bolsas e 57_2016'!#REF!
Name listaB: 'Valores bolsas e 57_2016'!$A$1:$B$9
Name Listas: [4]Folha1!$A$18:$A$90
Name LISTAZ: [5]Folha1!$A$18:$A$90
Name RespostaList: [3]dados_aux!$B$48:$B$50
Name RHExistNivelQualificList: [3]dados_aux!$B$100:$B$108
Name S_N: [2]Tabelas!$AF$1:$AF$2
Name SituacaoActual: [2]Tabelas!$AH$1:$AH$3
Name SNC: '[1]Listas para formulário'!$C$2:$C$23
Name Tipo_de_RH: [3]dados_aux!$B$82:$B$97
Name TipodeProteccao: [2]Tabelas!$AC$1:$AC$6

Sheet 2.Equipa de Investigação
G10: Montante associado à OCS | H10: 4320 | I10: 1ETI/MÊS
B11: 2. DETALHE DE EQUIPA POR ANO
F12: FTE
B13: Beneficiário | C13: Afetação para o Cálculo de Financiamento | D13: NOME | E13: Vínculo | F13: 2024 | G13: 2025 | H13: 2026 | I13: 2027 | J13: Total
B14: Universidade do Algarve | C14: Sim | D14: José Paulo Monteiro | E14: Contrato trabalho com o beneficiário | F14: 0 | G14: =SUMIF(CRONOGRAMA!#REF!,D14,CRONOGRAMA!#REF!) -> #REF! | H14: =SUMIF(CRONOGRAMA!#REF!,D14,CRONOGRAMA!#REF!) -> #REF! | I14: =SUMIF(CRONOGRAMA!#REF!,D14,CRONOGRAMA!#REF!) -> #REF! | J14: =SUM(F14:I14) -> #REF!
B15: Universidade do Algarve | C15: Sim | D15: Maria Conceição Neves | E15: Contrato trabalho com o beneficiário | F15: 0 | G15: =SUMIF(CRONOGRAMA!#REF!,D15,CRONOGRAMA!#REF!) -> #REF! | H15: =SUMIF(CRONOGRAMA!#REF!,D15,CRONOGRAMA!#REF!) -> #REF! | I15: =SUMIF(CRONOGRAMA!#REF!,D15,CRONOGRAMA!#REF!) -> #REF! | J15: =SUM(F15:I15) -> #REF!
F16: 0 | G16: =SUMIF(CRONOGRAMA!#REF!,D16,CRONOGRAMA!#REF!) -> #REF! | H16: =SUMIF(CRONOGRAMA!#REF!,D16,CRONOGRAMA!#REF!) -> #REF! | I16: =SUMIF(CRONOGRAMA!#REF!,D16,CRONOGRAMA!#REF!) -> #REF! | J16: =SUM(F16:I16) -> #REF! | K16: -
F17: 0 | G17: =SUMIF(CRONOGRAMA!#REF!,D17,CRONOGRAMA!#REF!) -> #REF! | H17: =SUMIF(CRONOGRAMA!#REF!,D17,CRONOGRAMA!#REF!) -> #REF! | I17: =SUMIF(CRONOGRAMA!#REF!,D17,CRONOGRAMA!#REF!) -> #REF! | J17: =SUM(F17:I17) -> #REF!
F18: 0 | G18: =SUMIF(CRONOGRAMA!#REF!,D18,CRONOGRAMA!#REF!) -> #REF! | H18: =SUMIF(CRONOGRAMA!#REF!,D18,CRONOGRAMA!#REF!) -> #REF! | I18: =SUMIF(CRONOGRAMA!#REF!,D18,CRONOGRAMA!#REF!) -> #REF! | J18: =SUM(F18:I18) -> #REF!
F19: 0 | G19: =SUMIF(CRONOGRAMA!#REF!,D19,CRONOGRAMA!#REF!) -> #REF! | H19: =SUMIF(CRONOGRAMA!#REF!,D19,CRONOGRAMA!#REF!) -> #REF! | I19: =SUMIF(CRONOGRAMA!#REF!,D19,CRONOGRAMA!#REF!) -> #REF! | J19: =SUM(F19:I19) -> #REF!
F20: 0 | G20: =SUMIF(CRONOGRAMA!#REF!,D20,CRONOGRAMA!#REF!) -> #REF! | H20: =SUMIF(CRONOGRAMA!#REF!,D20,CRONOGRAMA!#REF!) -> #REF! | I20: =SUMIF(CRONOGRAMA!#REF!,D20,CRONOGRAMA!#REF!) -> #REF! | J20: =SUM(F20:I20) -> #REF!
F21: 0 | G21: =SUMIF(CRONOGRAMA!#REF!,D21,CRONOGRAMA!#REF!) -> #REF! | H21: =SUMIF(CRONOGRAMA!#REF!,D21,CRONOGRAMA!#REF!) -> #REF! | I21: =SUMIF(CRONOGRAMA!#REF!,D21,CRONOGRAMA!#REF!) -> #REF! | J21: =SUM(F21:I21) -> #REF! | K21: -
F22: 0 | G22: =SUMIF(CRONOGRAMA!#REF!,D22,CRONOGRAMA!#REF!) -> #REF! | H22: =SUMIF(CRONOGRAMA!#REF!,D22,CRONOGRAMA!#REF!) -> #REF! | I22: =SUMIF(CRONOGRAMA!#REF!,D22,CRONOGRAMA!#REF!) -> #REF! | J22: =SUM(F22:I22) -> #REF!
F23: 0 | G23: =SUMIF(CRONOGRAMA!#REF!,D23,CRONOGRAMA!#REF!) -> #REF! | H23: =SUMIF(CRONOGRAMA!#REF!,D23,CRONOGRAMA!#REF!) -> #REF! | I23: =SUMIF(CRONOGRAMA!#REF!,D23,CRONOGRAMA!#REF!) -> #REF! | J23: =SUM(F23:I23) -> #REF!
F24: 0 | G24: =SUMIF(CRONOGRAMA!#REF!,D24,CRONOGRAMA!#REF!) -> #REF! | H24: =SUMIF(CRONOGRAMA!#REF!,D24,CRONOGRAMA!#REF!) -> #REF! | I24: =SUMIF(CRONOGRAMA!#REF!,D24,CRONOGRAMA!#REF!) -> #REF! | J24: =SUM(F24:I24) -> #REF!
F25: 0 | G25: =SUMIF(CRONOGRAMA!#REF!,D25,CRONOGRAMA!#REF!) -> #REF! | H25: =SUMIF(CRONOGRAMA!#REF!,D25,CRONOGRAMA!#REF!) -> #REF! | I25: =SUMIF(CRONOGRAMA!#REF!,D25,CRONOGRAMA!#REF!) -> #REF! | J25: =SUM(F25:I25) -> #REF!
F26: 0 | G26: =SUMIF(CRONOGRAMA!#REF!,D26,CRONOGRAMA!#REF!) -> #REF! | H26: =SUMIF(CRONOGRAMA!#REF!,D26,CRONOGRAMA!#REF!) -> #REF! | I26: =SUMIF(CRONOGRAMA!#REF!,D26,CRONOGRAMA!#REF!) -> #REF! | J26: =SUM(F26:I26) -> #REF!
F27: 0 | G27: =SUMIF(CRONOGRAMA!#REF!,D27,CRONOGRAMA!#REF!) -> #REF! | H27: =SUMIF(CRONOGRAMA!#REF!,D27,CRONOGRAMA!#REF!) -> #REF! | I27: =SUMIF(CRONOGRAMA!#REF!,D27,CRONOGRAMA!#REF!) -> #REF! | J27: =SUM(F27:I27) -> #REF!
E28: TOTAL | F28: 0 | G28: =SUM(G14:G27) -> #REF! | H28: =SUM(H14:H27) -> #REF! | I28: =SUM(I14:I27) -> #REF! | J28: =SUM(J14:J27) -> #REF! | K28: =J28-J16-J21 -> #REF!
E29: TOTAL FINANCEIRO
B31: 2. QUADRO FINANCEIRO
B33: Beneficiário | D33: FTE | E33: CUSTO TOTAL
B34: =+CRONOGRAMA!#REF! -> #REF! | D34: =SUMIFS($J$14:$J$27,$B$14:$B$27,B34,$C$14:$C$27,"Sim") -> 0 | E34: =+D34*H10 -> 0 | F34: (Valor a ser distribuído da Universidade do Algarve)
B35: =+CRONOGRAMA!#REF! -> #REF! | D35: =SUMIFS($J$14:$J$27,$B$14:$B$27,B35,$C$14:$C$27,"Sim") -> 0 | E35: =+D35*$H$10 -> 0
B36: =+CRONOGRAMA!#REF! -> #REF! | D36: =SUMIFS($J$14:$J$27,$B$14:$B$27,B36,$C$14:$C$27,"Sim") -> 0 | E36: =+D36*$H$10 -> 0
B37: TOTAL | D37: =SUM(D34:D35) -> 0 | E37: =SUM(E34:E35) -> 0

Sheet RESUMO
C10: Informações: Formulário elaborado para uso interno de docentes e investigadores da Universidade do Algarve, destinado a auxilar na elaboração de orçamentos de candidaturas a submeter ao concurso MPr-2023-7: SIID – I&D Empresarial - Operações em Copromoção - Outros territórios , promovido pelo Algarve 2030 . As células assinaladas a cor azul correspondem campos de preenchimento obrigatório. O projeto tem que que ser validado pela Divisão de Informação e Estatística (DIE) juntamente com a folha de cálculo deve ser enviado o overview do projeto.
C14: A. Programa Financiador: ALGARVE 2030 B. Para as ENESII: A taxa máxima de financiamento FEDER das operações elegíveis para o ALGARVE 2030 é de 75%. Todavia a taxa pode ser de 80% nos termos do nº10 do 133º do REITD em caso de superação das metas contratualizadas em todos os indicadores de resultado. C. Duração máxima dos projetos: 36 meses, exceto em casos devidamente justificados. D. Custos elegíveis: os custos das operações serão exclusivamente financiados através da metodologia de custos simplificados, na modalidade de custos unitários (custo unitário por FTE/ ETI – full time equivalent/ equivalente a tempo integral). O custo por FTE/ETI é de 4.320Euros E. Orçamento total: o projeto deve integrar um investimento elegível mínimo de 150.000 €. O montante do investimento é atingido pelos FTEs/ ETIs do projeto.
C17: PROJETO
C19: Aviso | E19: SACCT- Projetos de investigação Científica e Desenvolvim ento Tecnológico
C21: Beneficiário principal | E21: Universidade do Algarve | N21: NIF:
C23: Acrónimo e Título | E23: OAKHIMEDES - Adaptações dos sobreiros face às alterações climáticas e como as mesmas promovem a sustentabilidade do ecossistema
C25: Referência
C27: IR na UAlg | E27: Ana Cristina Coelho
C29: Unid. Orgânica | G29: Unidade I&D
C32: Data início | E32: 46296 | F32: (Campo Obrigatório)
C33: Duração Nº Meses | E33: 36 | F33: (Campo Obrigatório)
C34: Data de fim | E34: =IF(E33=0,"",EDATE(E32,E33)-1) -> 47391
C37: ORÇAMENTO
C39: Orçamento elegível | F39: =+BUDGET!G34 -> 580219.2
C40: Taxa de overheads | F40: 0.25
C41: Overheads | F41: =+BUDGET!G33 -> 116043.84
C51: 46387 | E51: =+E32 -> 46296 | F51: =IF(YEAR(C51)=YEAR(E51),MONTH(C51-E51),MONTH(E32-C52)) -> 3
C52: 46387 | E52: =IF(E34=1-1-2026,E34,"01-01-2026") -> 01-01-2026 | F52: =MONTH(C52-E52) -> 12
C53: 46752 | E53: =IF(E34=1-1-2027,E34,"01-01-2027") -> 01-01-2027 | F53: =MONTH(C53-E53) -> 12
C54: 47118 | E54: =IF(E34<=1-1-2028,E34,"01-01-2028") -> 01-01-2028 | F54: =MONTH(C54-E54) -> 12
C55: 47483 | E55: =E34 -> 47391 | F55: =IF(E55="","",MONTH(E55)) -> 9

Sheet ATIVIDADES
P3: Investigação Industrial
P4: Desenvolvimento Experimental
P5: Divulgação e Promoção
P6: Gestão Projeto
C10: Informações: Formulário elaborado para uso interno de docentes e investigadores da Universidade do Algarve, destinado a auxilar na elaboração de orçamentos de candidaturas a submeter ao concurso MPr-2023-7: SIID – I&D Empresarial - Operações em Copromoção - Outros territórios , promovido pelo Algarve 2030 . As células assinaladas a cor azul correspondem campos de preenchimento obrigatório. O projeto tem que que ser validado pela Divisão de Informação e Estatística (DIE) juntamente com a folha de cálculo deve ser enviado o overview do projeto.
C15: ATIVIDADES
C17: Número | D17: Designação | E17: Data de Início | F17: Duração | G17: Data de Fim | H17: Classificação
C18: A1 | D18: Gestão e Coordenação | E18: 46296 | F18: 36 | G18: =IF(OR(E18="",F18="",F18=0),"",EDATE(E18,F18)-1) -> 47391 | H18: Gestão Projeto
C19: A2 | D19: Avaliação da vitalidade das árvores | E19: 46388 | F19: 25 | G19: =IF(OR(E19="",F19="",F19=0),"",EDATE(E19,F19)-1) -> 47149 | H19: Desenvolvimento Experimental
C20: A3 | D20: Ambiente | E20: 46388 | F20: 25 | G20: =IF(OR(E20="",F20="",F20=0),"",EDATE(E20,F20)-1) -> 47149 | H20: Desenvolvimento Experimental
C21: A4 | D21: Homeostasia e genética | E21: 46388 | F21: 25 | G21: =IF(OR(E21="",F21="",F21=0),"",EDATE(E21,F21)-1) -> 47149 | H21: Desenvolvimento Experimental
C22: A5 | D22: Análise e interpretação dos dados | E22: 46753 | F22: 19 | G22: =IF(OR(E22="",F22="",F22=0),"",EDATE(E22,F22)-1) -> 47330 | H22: Desenvolvimento Experimental
C23: A6 | D23: Partilha de conhecimento | E23: 46753 | F23: 21 | G23: =IF(OR(E23="",F23="",F23=0),"",EDATE(E23,F23)-1) -> 47391 | H23: Divulgação e Promoção
C24: A7
C25: A8 | G25: =IF(OR(E25="",F25="",F25=0),"",EDATE(E25,F25)-1)
C26: A9 | G26: =IF(OR(E26="",F26="",F26=0),"",EDATE(E26,F26)-1)
C27: A10 | G27: =IF(OR(E27="",F27="",F27=0),"",EDATE(E27,F27)-1)
C28: A11 | G28: =IF(OR(E28="",F28="",F28=0),"",EDATE(E28,F28)-1)

Sheet CRONOGRAMA
B11: 1.DISTRIBUIÇÂO DA EQUIPA POR ATIVIDADES E POR EQUIPA DE INVESTIGAÇÂO
B13: Atividade | C13: Início (dd-mm-aaaaa) | D13: Duração (meses) | E13: Fim (dd-mm-aaaaa) | F13: =IF(F14<>"",IF(RESUMO!$E$32="","",DATE(YEAR(RESUMO!$E$32),MONTH(RESUMO!$E$32),DAY(RESUMO!$E$32))),"") -> 46296 | G13: =IF(G14<>"",IF(RESUMO!$E$32="","",DATE(YEAR(RESUMO!$E$32),MONTH(RESUMO!$E$32)+F14,DAY(RESUMO!$E$32))),"") -> 46327 | H13: =IF(H14<>"",IF(RESUMO!$E$32="","",DATE(YEAR(RESUMO!$E$32),MONTH(RESUMO!$E$32)+G14,DAY(RESUMO!$E$32))),"") -> 46357 | I13: =IF(I14<>"",IF(RESUMO!$E$32="","",DATE(YEAR(RESUMO!$E$32),MONTH(RESUMO!$E$32)+H14,DAY(RESUMO!$E$32))),"") -> 46388 | J13: =IF(J14<>"",IF(RESUMO!$E$32="","",DATE(YEAR(RESUMO!$E$32),MONTH(RESUMO!$E$32)+I14,DAY(RESUMO!$E$32))),"") -> 46419 | K13: =IF(K14<>"",IF(RESUMO!$E$32="","",DATE(YEAR(RESUMO!$E$32),MONTH(RESUMO!$E$32)+J14,DAY(RESUMO!$E$32))),"") -> 46447 | L13: =IF(L14<>"",IF(RESUMO!$E$32="","",DATE(YEAR(RESUMO!$E$32),MONTH(RESUMO!$E$32)+K14,DAY(RESUMO!$E$32))),"") -> 46478 | M13: =IF(M14<>"",IF(RESUMO!$E$32="","",DATE(YEAR(RESUMO!$E$32),MONTH(RESUMO!$E$32)+L14,DAY(RESUMO!$E$32))),"") -> 46508 | N13: =IF(N14<>"",IF(RESUMO!$E$32="","",DATE(YEAR(RESUMO!$E$32),MONTH(RESUMO!$E$32)+M14,DAY(RESUMO!$E$32))),"") -> 46539 | ... AO13: =IF(AO14<>"",IF(RESUMO!$E$32="","",DATE(YEAR(RESUMO!$E$32),MONTH(RESUMO!$E$32)+AN14,DAY(RESUMO!$E$32))),"") -> 47362
F14: =IF(RESUMO!$E$33>0,1,"") -> 1 | G14: =IF(RESUMO!$E$33>0,F14+1,"") -> 2 | H14: =IF(RESUMO!$E$33>0,G14+1,"") -> 3 | I14: =IF(RESUMO!$E$33>0,H14+1,"") -> 4 | J14: =IF(RESUMO!$E$33>0,I14+1,"") -> 5 | K14: =IF(RESUMO!$E$33>0,J14+1,"") -> 6 | L14: =IF(RESUMO!$E$33>0,K14+1,"") -> 7 | M14: =IF(RESUMO!$E$33>0,L14+1,"") -> 8 | N14: =IF(RESUMO!$E$33>0,M14+1,"") -> 9 | ... AO14: =IF(RESUMO!$E$33>0,AN14+1,"") -> 36
B16: =IF(ATIVIDADES!D18>0,ATIVIDADES!D18,"") -> Gestão e Coordenação | C16: =IF(B16="","",VLOOKUP(B16,ATIVIDADES!$D$17:$F$23,2,FALSE)) -> 46296 | D16: =IF(B16="","",VLOOKUP(B16,ATIVIDADES!$D$18:$F$23,3,FALSE)) -> 36 | E16: =IF(OR(C16="",D16="",D16=0),"",EDATE(C16,D16)-1) -> 47391 | F16: =IF(OR($C16="",$D16=""),0,IF(AND($C16<=F$13,$E16>=F$13),1,0)) -> 1 | G16: =IF(OR($C16="",$D16=""),0,IF(AND($C16<=G$13,$E16>=G$13),F16+1,0)) -> 2 | H16: =IF(OR($C16="",$D16=""),0,IF(AND($C16<=H$13,$E16>=H$13),G16+1,0)) -> 3 | I16: =IF(OR($C16="",$D16=""),0,IF(AND($C16<=I$13,$E16>=I$13),H16+1,0)) -> 4 | J16: =IF(OR($C16="",$D16=""),0,IF(AND($C16<=J$13,$E16>=J$13),I16+1,0)) -> 5 | K16: =IF(OR($C16="",$D16=""),0,IF(AND($C16<=K$13,$E16>=K$13),J16+1,0)) -> 6 | L16: =IF(OR($C16="",$D16=""),0,IF(AND($C16<=L$13,$E16>=L$13),K16+1,0)) -> 7 | M16: =IF(OR($C16="",$D16=""),0,IF(AND($C16<=M$13,$E16>=M$13),L16+1,0)) -> 8 | N16: =IF(OR($C16="",$D16=""),0,IF(AND($C16<=N$13,$E16>=N$13),M16+1,0)) -> 9 | ... AO16: =IF(OR($C16="",$D16=""),0,IF(AND($C16<=AO$13,$E16>=AO$13),AN16+1,0)) -> 36
B17: =IF(ATIVIDADES!D19>0,ATIVIDADES!D19,"") -> Avaliação da vitalidade das árvores | C17: =IF(B17="","",VLOOKUP(B17,ATIVIDADES!$D$17:$F$23,2,FALSE)) -> 46388 | D17: =IF(B17="","",VLOOKUP(B17,ATIVIDADES!$D$18:$F$23,3,FALSE)) -> 25 | E17: =IF(OR(C17="",D17="",D17=0),"",EDATE(C17,D17)-1) -> 47149 | F17: =IF(OR($C17="",$D17=""),0,IF(AND($C17<=F$13,$E17>=F$13),1,0)) -> 0 | G17: =IF(OR($C17="",$D17=""),0,IF(AND($C17<=G$13,$E17>=G$13),F17+1,0)) -> 0 | H17: =IF(OR($C17="",$D17=""),0,IF(AND($C17<=H$13,$E17>=H$13),G17+1,0)) -> 0 | I17: =IF(OR($C17="",$D17=""),0,IF(AND($C17<=I$13,$E17>=I$13),H17+1,0)) -> 1 | J17: =IF(OR($C17="",$D17=""),0,IF(AND($C17<=J$13,$E17>=J$13),I17+1,0)) -> 2 | K17: =IF(OR($C17="",$D17=""),0,IF(AND($C17<=K$13,$E17>=K$13),J17+1,0)) -> 3 | L17: =IF(OR($C17="",$D17=""),0,IF(AND($C17<=L$13,$E17>=L$13),K17+1,0)) -> 4 | M17: =IF(OR($C17="",$D17=""),0,IF(AND($C17<=M$13,$E17>=M$13),L17+1,0)) -> 5 | N17: =IF(OR($C17="",$D17=""),0,IF(AND($C17<=N$13,$E17>=N$13),M17+1,0)) -> 6 | ... AO17: =IF(OR($C17="",$D17=""),0,IF(AND($C17<=AO$13,$E17>=AO$13),AN17+1,0)) -> 0
B18: =IF(ATIVIDADES!D20>0,ATIVIDADES!D20,"") -> Ambiente | C18: =IF(B18="","",VLOOKUP(B18,ATIVIDADES!$D$17:$F$23,2,FALSE)) -> 46388 | D18: =IF(B18="","",VLOOKUP(B18,ATIVIDADES!$D$18:$F$23,3,FALSE)) -> 25 | E18: =IF(OR(C18="",D18="",D18=0),"",EDATE(C18,D18)-1) -> 47149 | F18: =IF(OR($C18="",$D18=""),0,IF(AND($C18<=F$13,$E18>=F$13),1,0)) -> 0 | G18: =IF(OR($C18="",$D18=""),0,IF(AND($C18<=G$13,$E18>=G$13),F18+1,0)) -> 0 | H18: =IF(OR($C18="",$D18=""),0,IF(AND($C18<=H$13,$E18>=H$13),G18+1,0)) -> 0 | I18: =IF(OR($C18="",$D18=""),0,IF(AND($C18<=I$13,$E18>=I$13),H18+1,0)) -> 1 | J18: =IF(OR($C18="",$D18=""),0,IF(AND($C18<=J$13,$E18>=J$13),I18+1,0)) -> 2 | K18: =IF(OR($C18="",$D18=""),0,IF(AND($C18<=K$13,$E18>=K$13),J18+1,0)) -> 3 | L18: =IF(OR($C18="",$D18=""),0,IF(AND($C18<=L$13,$E18>=L$13),K18+1,0)) -> 4 | M18: =IF(OR($C18="",$D18=""),0,IF(AND($C18<=M$13,$E18>=M$13),L18+1,0)) -> 5 | N18: =IF(OR($C18="",$D18=""),0,IF(AND($C18<=N$13,$E18>=N$13),M18+1,0)) -> 6 | ... AO18: =IF(OR($C18="",$D18=""),0,IF(AND($C18<=AO$13,$E18>=AO$13),AN18+1,0)) -> 0
B19: =IF(ATIVIDADES!D21>0,ATIVIDADES!D21,"") -> Homeostasia e genética | C19: =IF(B19="","",VLOOKUP(B19,ATIVIDADES!$D$17:$F$23,2,FALSE)) -> 46388 | D19: =IF(B19="","",VLOOKUP(B19,ATIVIDADES!$D$18:$F$23,3,FALSE)) -> 25 | E19: =IF(OR(C19="",D19="",D19=0),"",EDATE(C19,D19)-1) -> 47149 | F19: =IF(OR($C19="",$D19=""),0,IF(AND($C19<=F$13,$E19>=F$13),1,0)) -> 0 | G19: =IF(OR($C19="",$D19=""),0,IF(AND($C19<=G$13,$E19>=G$13),F19+1,0)) -> 0 | H19: =IF(OR($C19="",$D19=""),0,IF(AND($C19<=H$13,$E19>=H$13),G19+1,0)) -> 0 | I19: =IF(OR($C19="",$D19=""),0,IF(AND($C19<=I$13,$E19>=I$13),H19+1,0)) -> 1 | J19: =IF(OR($C19="",$D19=""),0,IF(AND($C19<=J$13,$E19>=J$13),I19+1,0)) -> 2 | K19: =IF(OR($C19="",$D19=""),0,IF(AND($C19<=K$13,$E19>=K$13),J19+1,0)) -> 3 | L19: =IF(OR($C19="",$D19=""),0,IF(AND($C19<=L$13,$E19>=L$13),K19+1,0)) -> 4 | M19: =IF(OR($C19="",$D19=""),0,IF(AND($C19<=M$13,$E19>=M$13),L19+1,0)) -> 5 | N19: =IF(OR($C19="",$D19=""),0,IF(AND($C19<=N$13,$E19>=N$13),M19+1,0)) -> 6 | ... AO19: =IF(OR($C19="",$D19=""),0,IF(AND($C19<=AO$13,$E19>=AO$13),AN19+1,0)) -> 0
B20: =IF(ATIVIDADES!D22>0,ATIVIDADES!D22,"") -> Análise e interpretação dos dados | C20: =IF(B20="","",VLOOKUP(B20,ATIVIDADES!$D$17:$F$23,2,FALSE)) -> 46753 | D20: =IF(B20="","",VLOOKUP(B20,ATIVIDADES!$D$18:$F$23,3,FALSE)) -> 19 | E20: =IF(OR(C20="",D20="",D20=0),"",EDATE(C20,D20)-1) -> 47330 | F20: =IF(OR($C20="",$D20=""),0,IF(AND($C20<=F$13,$E20>=F$13),1,0)) -> 0 | G20: =IF(OR($C20="",$D20=""),0,IF(AND($C20<=G$13,$E20>=G$13),F20+1,0)) -> 0 | H20: =IF(OR($C20="",$D20=""),0,IF(AND($C20<=H$13,$E20>=H$13),G20+1,0)) -> 0 | I20: =IF(OR($C20="",$D20=""),0,IF(AND($C20<=I$13,$E20>=I$13),H20+1,0)) -> 0 | J20: =IF(OR($C20="",$D20=""),0,IF(AND($C20<=J$13,$E20>=J$13),I20+1,0)) -> 0 | K20: =IF(OR($C20="",$D20=""),0,IF(AND($C20<=K$13,$E20>=K$13),J20+1,0)) -> 0 | L20: =IF(OR($C20="",$D20=""),0,IF(AND($C20<=L$13,$E20>=L$13),K20+1,0)) -> 0 | M20: =IF(OR($C20="",$D20=""),0,IF(AND($C20<=M$13,$E20>=M$13),L20+1,0)) -> 0 | N20: =IF(OR($C20="",$D20=""),0,IF(AND($C20<=N$13,$E20>=N$13),M20+1,0)) -> 0 | ... AO20: =IF(OR($C20="",$D20=""),0,IF(AND($C20<=AO$13,$E20>=AO$13),AN20+1,0)) -> 0
B21: =IF(ATIVIDADES!D23>0,ATIVIDADES!D23,"") -> Partilha de conhecimento | C21: =IF(B21="","",VLOOKUP(B21,ATIVIDADES!$D$17:$F$23,2,FALSE)) -> 46753 | D21: =IF(B21="","",VLOOKUP(B21,ATIVIDADES!$D$18:$F$23,3,FALSE)) -> 21 | E21: =IF(OR(C21="",D21="",D21=0),"",EDATE(C21,D21)-1) -> 47391 | F21: =IF(OR($C21="",$D21=""),0,IF(AND($C21<=F$13,$E21>=F$13),1,0)) -> 0 | G21: =IF(OR($C21="",$D21=""),0,IF(AND($C21<=G$13,$E21>=G$13),F21+1,0)) -> 0 | H21: =IF(OR($C21="",$D21=""),0,IF(AND($C21<=H$13,$E21>=H$13),G21+1,0)) -> 0 | I21: =IF(OR($C21="",$D21=""),0,IF(AND($C21<=I$13,$E21>=I$13),H21+1,0)) -> 0 | J21: =IF(OR($C21="",$D21=""),0,IF(AND($C21<=J$13,$E21>=J$13),I21+1,0)) -> 0 | K21: =IF(OR($C21="",$D21=""),0,IF(AND($C21<=K$13,$E21>=K$13),J21+1,0)) -> 0 | L21: =IF(OR($C21="",$D21=""),0,IF(AND($C21<=L$13,$E21>=L$13),K21+1,0)) -> 0 | M21: =IF(OR($C21="",$D21=""),0,IF(AND($C21<=M$13,$E21>=M$13),L21+1,0)) -> 0 | N21: =IF(OR($C21="",$D21=""),0,IF(AND($C21<=N$13,$E21>=N$13),M21+1,0)) -> 0 | ... AO21: =IF(OR($C21="",$D21=""),0,IF(AND($C21<=AO$13,$E21>=AO$13),AN21+1,0)) -> 21
B22: =IF(ATIVIDADES!D24>0,ATIVIDADES!D24,"") | C22: =IF(B22="","",VLOOKUP(B22,ATIVIDADES!$D$17:$F$23,2,FALSE)) | D22: =IF(B22="","",VLOOKUP(B22,ATIVIDADES!$D$18:$F$23,3,FALSE)) | E22: =IF(OR(C22="",D22="",D22=0),"",EDATE(C22,D22)-1) | F22: =IF(OR($C22="",$D22=""),0,IF(AND($C22<=F$13,$E22>=F$13),1,0)) -> 0 | G22: =IF(OR($C22="",$D22=""),0,IF(AND($C22<=G$13,$E22>=G$13),F22+1,0)) -> 0 | H22: =IF(OR($C22="",$D22=""),0,IF(AND($C22<=H$13,$E22>=H$13),G22+1,0)) -> 0 | I22: =IF(OR($C22="",$D22=""),0,IF(AND($C22<=I$13,$E22>=I$13),H22+1,0)) -> 0 | J22: =IF(OR($C22="",$D22=""),0,IF(AND($C22<=J$13,$E22>=J$13),I22+1,0)) -> 0 | K22: =IF(OR($C22="",$D22=""),0,IF(AND($C22<=K$13,$E22>=K$13),J22+1,0)) -> 0 | L22: =IF(OR($C22="",$D22=""),0,IF(AND($C22<=L$13,$E22>=L$13),K22+1,0)) -> 0 | M22: =IF(OR($C22="",$D22=""),0,IF(AND($C22<=M$13,$E22>=M$13),L22+1,0)) -> 0 | N22: =IF(OR($C22="",$D22=""),0,IF(AND($C22<=N$13,$E22>=N$13),M22+1,0)) -> 0 | ... AO22: =IF(OR($C22="",$D22=""),0,IF(AND($C22<=AO$13,$E22>=AO$13),AN22+1,0)) -> 0
B23: =IF(ATIVIDADES!D25>0,ATIVIDADES!D25,"") | C23: =IF(B23="","",VLOOKUP(B23,ATIVIDADES!$D$17:$F$23,2,FALSE)) | D23: =IF(B23="","",VLOOKUP(B23,ATIVIDADES!$D$18:$F$23,3,FALSE)) | E23: =IF(OR(C23="",D23="",D23=0),"",EDATE(C23,D23)-1) | F23: =IF(OR($C23="",$D23=""),0,IF(AND($C23<=F$13,$E23>=F$13),1,0)) -> 0 | G23: =IF(OR($C23="",$D23=""),0,IF(AND($C23<=G$13,$E23>=G$13),F23+1,0)) -> 0 | H23: =IF(OR($C23="",$D23=""),0,IF(AND($C23<=H$13,$E23>=H$13),G23+1,0)) -> 0 | I23: =IF(OR($C23="",$D23=""),0,IF(AND($C23<=I$13,$E23>=I$13),H23+1,0)) -> 0 | J23: =IF(OR($C23="",$D23=""),0,IF(AND($C23<=J$13,$E23>=J$13),I23+1,0)) -> 0 | K23: =IF(OR($C23="",$D23=""),0,IF(AND($C23<=K$13,$E23>=K$13),J23+1,0)) -> 0 | L23: =IF(OR($C23="",$D23=""),0,IF(AND($C23<=L$13,$E23>=L$13),K23+1,0)) -> 0 | M23: =IF(OR($C23="",$D23=""),0,IF(AND($C23<=M$13,$E23>=M$13),L23+1,0)) -> 0 | N23: =IF(OR($C23="",$D23=""),0,IF(AND($C23<=N$13,$E23>=N$13),M23+1,0)) -> 0 | ... AO23: =IF(OR($C23="",$D23=""),0,IF(AND($C23<=AO$13,$E23>=AO$13),AN23+1,0)) -> 0
B24: =IF(ATIVIDADES!D26>0,ATIVIDADES!D26,"") | C24: =IF(B24="","",VLOOKUP(B24,ATIVIDADES!$D$17:$F$23,2,FALSE)) | D24: =IF(B24="","",VLOOKUP(B24,ATIVIDADES!$D$18:$F$23,3,FALSE)) | E24: =IF(OR(C24="",D24="",D24=0),"",EDATE(C24,D24)-1) | F24: =IF(OR($C24="",$D24=""),0,IF(AND($C24<=F$13,$E24>=F$13),1,0)) -> 0 | G24: =IF(OR($C24="",$D24=""),0,IF(AND($C24<=G$13,$E24>=G$13),F24+1,0)) -> 0 | H24: =IF(OR($C24="",$D24=""),0,IF(AND($C24<=H$13,$E24>=H$13),G24+1,0)) -> 0 | I24: =IF(OR($C24="",$D24=""),0,IF(AND($C24<=I$13,$E24>=I$13),H24+1,0)) -> 0 | J24: =IF(OR($C24="",$D24=""),0,IF(AND($C24<=J$13,$E24>=J$13),I24+1,0)) -> 0 | K24: =IF(OR($C24="",$D24=""),0,IF(AND($C24<=K$13,$E24>=K$13),J24+1,0)) -> 0 | L24: =IF(OR($C24="",$D24=""),0,IF(AND($C24<=L$13,$E24>=L$13),K24+1,0)) -> 0 | M24: =IF(OR($C24="",$D24=""),0,IF(AND($C24<=M$13,$E24>=M$13),L24+1,0)) -> 0 | N24: =IF(OR($C24="",$D24=""),0,IF(AND($C24<=N$13,$E24>=N$13),M24+1,0)) -> 0 | ... AO24: =IF(OR($C24="",$D24=""),0,IF(AND($C24<=AO$13,$E24>=AO$13),AN24+1,0)) -> 0
B25: =IF(ATIVIDADES!D27>0,ATIVIDADES!D27,"") | C25: =IF(B25="","",VLOOKUP(B25,ATIVIDADES!$D$17:$F$23,2,FALSE)) | D25: =IF(B25="","",VLOOKUP(B25,ATIVIDADES!$D$18:$F$23,3,FALSE)) | E25: =IF(OR(C25="",D25="",D25=0),"",EDATE(C25,D25)-1) | F25: =IF(OR($C25="",$D25=""),0,IF(AND($C25<=F$13,$E25>=F$13),1,0)) -> 0 | G25: =IF(OR($C25="",$D25=""),0,IF(AND($C25<=G$13,$E25>=G$13),F25+1,0)) -> 0 | H25: =IF(OR($C25="",$D25=""),0,IF(AND($C25<=H$13,$E25>=H$13),G25+1,0)) -> 0 | I25: =IF(OR($C25="",$D25=""),0,IF(AND($C25<=I$13,$E25>=I$13),H25+1,0)) -> 0 | J25: =IF(OR($C25="",$D25=""),0,IF(AND($C25<=J$13,$E25>=J$13),I25+1,0)) -> 0 | K25: =IF(OR($C25="",$D25=""),0,IF(AND($C25<=K$13,$E25>=K$13),J25+1,0)) -> 0 | L25: =IF(OR($C25="",$D25=""),0,IF(AND($C25<=L$13,$E25>=L$13),K25+1,0)) -> 0 | M25: =IF(OR($C25="",$D25=""),0,IF(AND($C25<=M$13,$E25>=M$13),L25+1,0)) -> 0 | N25: =IF(OR($C25="",$D25=""),0,IF(AND($C25<=N$13,$E25>=N$13),M25+1,0)) -> 0 | ... AO25: =IF(OR($C25="",$D25=""),0,IF(AND($C25<=AO$13,$E25>=AO$13),AN25+1,0)) -> 0
B26: =IF(ATIVIDADES!D28>0,ATIVIDADES!D28,"") | C26: =IF(B26="","",VLOOKUP(B26,ATIVIDADES!$D$17:$F$23,2,FALSE)) | D26: =IF(B26="","",VLOOKUP(B26,ATIVIDADES!$D$18:$F$23,3,FALSE)) | E26: =IF(OR(C26="",D26="",D26=0),"",EDATE(C26,D26)-1) | F26: =IF(OR($C26="",$D26=""),0,IF(AND($C26<=F$13,$E26>=F$13),1,0)) -> 0 | G26: =IF(OR($C26="",$D26=""),0,IF(AND($C26<=G$13,$E26>=G$13),F26+1,0)) -> 0 | H26: =IF(OR($C26="",$D26=""),0,IF(AND($C26<=H$13,$E26>=H$13),G26+1,0)) -> 0 | I26: =IF(OR($C26="",$D26=""),0,IF(AND($C26<=I$13,$E26>=I$13),H26+1,0)) -> 0 | J26: =IF(OR($C26="",$D26=""),0,IF(AND($C26<=J$13,$E26>=J$13),I26+1,0)) -> 0 | K26: =IF(OR($C26="",$D26=""),0,IF(AND($C26<=K$13,$E26>=K$13),J26+1,0)) -> 0 | L26: =IF(OR($C26="",$D26=""),0,IF(AND($C26<=L$13,$E26>=L$13),K26+1,0)) -> 0 | M26: =IF(OR($C26="",$D26=""),0,IF(AND($C26<=M$13,$E26>=M$13),L26+1,0)) -> 0 | N26: =IF(OR($C26="",$D26=""),0,IF(AND($C26<=N$13,$E26>=N$13),M26+1,0)) -> 0 | ... AO26: =IF(OR($C26="",$D26=""),0,IF(AND($C26<=AO$13,$E26>=AO$13),AN26+1,0)) -> 0

Sheet RH_BOLSEIROS
V2: SIM
V3: NÃO
B9: SACCT-Projetos de Investigação Científica e Desenvolvimento Tecnológico (IC&DT)
B12: Pessoal técnico do beneficiário
B14: O PROJETO IRÁ TER BOLSEIROS DE INVESTIGAÇÃO | E14: SIM | F14: (preenchimento Obrigatório)
B16: Bolsas de Investigação
B18: Tipo de bolsa | C18: Valor mensal | D18: 2026 | H18: 2027 | L18: 2028 | P18: 2029 | T18: 2030 | X18: Total | Y18: Person-Month_FTE
D19: N.º Meses | E19: Seg. Social Voluntário | F19: Valor | G19: 2024 Total | H19: N.º Meses | I19: Seg. Social Voluntário | J19: Valor | K19: 2025 Total | L19: N.º Meses | M19: Seg. Social Voluntário | N19: Valor | O19: 2026 Total | P19: N.º Meses | Q19: Seg. Social Voluntário | R19: Valor | S19: 2027 Total | T19: N.º Meses | U19: Seg. Social Voluntário | V19: Valor | W19: 2028 Total
B20: Bolsas de Investigação (BI)- estudantes de doutoramento | C20: =VLOOKUP(B20,'Valores bolsas e 57_2016'!$A$1:$B$9,2,FALSE) -> 1309.64 | D20: 0 | E20: =D20*$AC$25 -> 0 | F20: =+C20*D20 -> 0 | G20: =E20+F20 -> 0 | H20: 12 | I20: =H20*$AC$25 -> 1855.92 | J20: =H20*$C$20 -> 15715.68 | K20: =I20+J20 -> 17571.6 | L20: 12 | M20: =L20*$AC$25 -> 1855.92 | N20: =L20*$C$20 -> 15715.68 | O20: =M20+N20 -> 17571.6 | P20: 6 | Q20: =P20*$AC$25 -> 927.96 | R20: =P20*$C$20 -> 7857.84 | S20: =Q20+R20 -> 8785.8 | T20: 0 | U20: =T20*$AC$25 -> 0 | V20: =T20*$C$20 -> 0 | W20: =U20+V20 -> 0 | X20: =+G20+K20+O20+S20 -> 43929 | Y20: =+T20+P20+L20+H20+D20 -> 30
B21: Bolsas de Investigação (BI)- estudantes de doutoramento | C21: =VLOOKUP(B21,'Valores bolsas e 57_2016'!$A$1:$B$9,2,FALSE) -> 1309.64 | D21: 0 | E21: =D21*$AC$25 -> 0 | F21: =+C21*D21 -> 0 | G21: =E21+F21 -> 0 | H21: 12 | I21: =H21*$AC$25 -> 1855.92 | J21: =H21*$C$21 -> 15715.68 | K21: =I21+J21 -> 17571.6 | L21: 12 | M21: =L21*$AC$25 -> 1855.92 | N21: =L21*$C$21 -> 15715.68 | O21: =M21+N21 -> 17571.6 | P21: 6 | Q21: =P21*$AC$25 -> 927.96 | R21: =P21*$C$21 -> 7857.84 | S21: =Q21+R21 -> 8785.8 | T21: 0 | U21: =T21*$AC$25 -> 0 | V21: =T21*$C$21 -> 0 | W21: =U21+V21 -> 0 | X21: =+G21+K21+O21+S21 -> 43929 | Y21: =+T21+P21+L21+H21+D21 -> 30
B22: Bolsas de investigação pós doutoral | C22: =VLOOKUP(B22,'Valores bolsas e 57_2016'!$A$1:$B$9,2,FALSE) -> 1851 | D22: 0 | E22: =D22*$AC$25 -> 0 | F22: =+C22*D22 -> 0 | G22: =E22+F22 -> 0 | H22: 12 | I22: =H22*$AC$25 -> 1855.92 | J22: =H22*$C$22 -> 22212 | K22: =I22+J22 -> 24067.92 | L22: 12 | M22: =L22*$AC$25 -> 1855.92 | N22: =L22*$C$22 -> 22212 | O22: =M22+N22 -> 24067.92 | P22: 6 | Q22: =P22*$AC$25 -> 927.96 | R22: =P22*$C$22 -> 11106 | S22: =Q22+R22 -> 12033.96 | T22: 0 | U22: =T22*$AC$25 -> 0 | V22: =T22*$C$22 -> 0 | W22: =U22+V22 -> 0 | X22: =+G22+K22+O22+S22 -> 60169.8 | Y22: =+T22+P22+L22+H22+D22 -> 30
B23: Sem bolsa | C23: =VLOOKUP(B23,'Valores bolsas e 57_2016'!$A$1:$B$9,2,FALSE) -> 0 | D23: 0 | E23: =D23*$AC$25 -> 0 | F23: =+C23*D23 -> 0 | G23: =E23+F23 -> 0 | H23: 0 | I23: =H23*$AC$25 -> 0 | J23: =H23*$C$23 -> 0 | K23: =I23+J23 -> 0 | M23: =L23*$AC$25 -> 0 | N23: =L23*$C$23 -> 0 | O23: =M23+N23 -> 0 | P23: 0 | Q23: =P23*$AC$25 -> 0 | R23: =P23*$C$23 -> 0 | S23: =Q23+R23 -> 0 | T23: 0 | U23: =T23*$AC$25 -> 0 | V23: =T23*$C$23 -> 0 | W23: =U23+V23 -> 0 | X23: =+G23+K23+O23+S23 -> 0 | Y23: =+T23+P23+L23+H23+D23 -> 0
B24: Total | E24: =SUM(E20:E23) -> 0 | F24: =SUM(F20:F23) -> 0 | G24: =SUM(G20:G23) -> 0 | I24: =SUM(I20:I23) -> 5567.76 | J24: =SUM(J20:J23) -> 53643.36 | K24: =SUM(K20:K23) -> 59211.12 | M24: =SUM(M20:M23) -> 5567.76 | N24: =SUM(N20:N23) -> 53643.36 | O24: =SUM(O20:O23) -> 59211.12 | Q24: =SUM(Q20:Q23) -> 2783.88 | R24: =SUM(R20:R23) -> 26821.68 | S24: =SUM(S20:S23) -> 29605.56 | U24: =SUM(U20:U23) -> 0 | V24: =SUM(V20:V23) -> 0 | W24: =SUM(W20:W23) -> 0 | X24: =SUM(X20:X23) -> 148027.8 | Z24: Seguro Social Voluntário
Y25: =SUM(Y20:Y23) -> 90 | Z25: 2025 | AA25: 0 | AC25: 154.66
B26: Regulamento das Bolsas

Sheet RH_CONTRATOS
B9: SACCT-Projetos de Investigação Científica e Desenvolvimento Tecnológico (IC&DT) | V9: SIM
V10: NÃO
B12: Pessoal técnico do beneficiário
B14: O PROJETO IRÁ CONTRATAR INVESTIGADORES | E14: NÃO | F14: (preenchimento Obrigatório)
B16: Pessoal a contratar Emprego Científico (DL n.º 57/2016 de 29-08)
B18: Emprego Científico - Contratos de Trabalho | C18: Remuneração Bruta | D18: 2025 | J18: 2026 | P18: 2027 | V18: 2028 | AB18: TOTAL
D19: Meses | E19: RbM | F19: Segurança Social | G19: Subsidio férias e Natal | H19: Subsidio Alimentação | I19: Custo total 2024 | J19: Meses | K19: RbM | L19: Segurança Social | M19: Subsidio férias e Natal | N19: Subsidio Alimentação | O19: Custo total 2025 | P19: Meses | Q19: RbM | R19: Segurança Social | S19: Subsidio férias e Natal | T19: Subsidio Alimentação | U19: Custo total 2026 | V19: Meses | W19: RbM | X19: Segurança Social | Y19: Subsidio férias e Natal | Z19: Subsidio Alimentação | AA19: Custo total 2027 | AB19: Meses | AC19: Valor
B20: Sem Contrato | C20: =VLOOKUP(B20,'Valores bolsas e 57_2016'!$A$7:$B$12,2,FALSE) -> 0 | D20: 0 | E20: =+C20*D20 -> 0 | F20: =(+E20*$C$26)+(G20*$C$26) -> 0 | G20: =+((D20/12)*2)*C20 -> 0 | H20: =IF(D20=0,0, $C$27*(D20-1)*22) -> 0 | I20: =+E20+F20+G20+H20 -> 0 | J20: 0 | K20: =+C20*J20 -> 0 | L20: =(+K20*$C$26)+(M20*$C$26) -> 0 | M20: =+((J20/12)*2)*C20 -> 0 | N20: =IF(J20=0,0, $C$27*(J20-1)*22) -> 0 | O20: =+K20+L20+M20+N20 -> 0 | P20: 0 | Q20: =+C20*P20 -> 0 | R20: =(+Q20*$C$26)+(S20*$C$26) -> 0 | S20: =+((P20/12)*2)*C20 -> 0 | T20: =IF(P20=0,0, $C$27*(P20-1)*22) -> 0 | U20: =+Q20+R20+S20+T20 -> 0 | V20: 0 | W20: =+C20*V20 -> 0 | X20: =(+W20*$C$26)+(Y20*$C$26) -> 0 | Y20: =+((V20/12)*2)*C20 -> 0 | Z20: =IF(V20=0,0, $C$27*(V20-1)*22) -> 0 | AA20: =+W20+X20+Y20+Z20 -> 0 | AB20: =+V20+P20+J20+D20 -> 0 | AC20: =+AA20+U20+O20+I20 -> 0
B21: Sem Contrato | C21: =VLOOKUP(B21,'Valores bolsas e 57_2016'!$A$7:$B$12,2,FALSE) -> 0 | D21: 0 | E21: =+C21*D21 -> 0 | F21: =(+E21*$C$26)+(G21*$C$26) -> 0 | G21: =+((D21/12)*2)*C21 -> 0 | H21: =IF(D21=0,0, $C$27*(D21-1)*22) -> 0 | I21: =+E21+F21+G21+H21 -> 0 | J21: 0 | K21: =+C21*J21 -> 0 | L21: =(+K21*$C$26)+(M21*$C$26) -> 0 | M21: =+((J21/12)*2)*C21 -> 0 | N21: =IF(J21=0,0, $C$27*(J21-1)*22) -> 0 | O21: =+K21+L21+M21+N21 -> 0 | P21: 0 | Q21: =+C21*P21 -> 0 | R21: =(+Q21*$C$26)+(S21*$C$26) -> 0 | S21: =+((P21/12)*2)*C21 -> 0 | T21: =IF(P21=0,0, $C$27*(P21-1)*22) -> 0 | U21: =+Q21+R21+S21+T21 -> 0 | V21: 0 | W21: =+C21*V21 -> 0 | X21: =(+W21*$C$26)+(Y21*$C$26) -> 0 | Y21: =+((V21/12)*2)*C21 -> 0 | Z21: =IF(V21=0,0, $C$27*(V21-1)*22) -> 0 | AA21: =+W21+X21+Y21+Z21 -> 0 | AB21: =+V21+P21+J21+D21 -> 0 | AC21: =+AA21+U21+O21+I21 -> 0
B22: Sem Contrato | C22: =VLOOKUP(B22,'Valores bolsas e 57_2016'!$A$7:$B$12,2,FALSE) -> 0 | D22: 0 | E22: =+C22*D22 -> 0 | F22: =(+E22*$C$26)+(G22*$C$26) -> 0 | G22: =+((D22/12)*2)*C22 -> 0 | H22: =IF(D22=0,0, $C$27*(D22-1)*22) -> 0 | I22: =+E22+F22+G22+H22 -> 0 | J22: 0 | K22: =+C22*J22 -> 0 | L22: =(+K22*$C$26)+(M22*$C$26) -> 0 | M22: =+((J22/12)*2)*C22 -> 0 | N22: =IF(J22=0,0, $C$27*(J22-1)*22) -> 0 | O22: =+K22+L22+M22+N22 -> 0 | P22: 0 | Q22: =+C22*P22 -> 0 | R22: =(+Q22*$C$26)+(S22*$C$26) -> 0 | S22: =+((P22/12)*2)*C22 -> 0 | T22: =IF(P22=0,0, $C$27*(P22-1)*22) -> 0 | U22: =+Q22+R22+S22+T22 -> 0 | V22: 0 | W22: =+C22*V22 -> 0 | X22: =(+W22*$C$26)+(Y22*$C$26) -> 0 | Y22: =+((V22/12)*2)*C22 -> 0 | Z22: =IF(V22=0,0, $C$27*(V22-1)*22) -> 0 | AA22: =+W22+X22+Y22+Z22 -> 0 | AB22: =+V22+P22+J22+D22 -> 0 | AC22: =+AA22+U22+O22+I22 -> 0
B23: Sem Contrato | C23: =VLOOKUP(B23,'Valores bolsas e 57_2016'!$A$7:$B$12,2,FALSE) -> 0 | D23: 0 | E23: =+C23*D23 -> 0 | F23: =(+E23*$C$26)+(G23*$C$26) -> 0 | G23: =+((D23/12)*2)*C23 -> 0 | H23: =IF(D23=0,0, $C$27*(D23-1)*22) -> 0 | I23: =+E23+F23+G23+H23 -> 0 | J23: 0 | K23: =+C23*J23 -> 0 | L23: =(+K23*$C$26)+(M23*$C$26) -> 0 | M23: =+((J23/12)*2)*C23 -> 0 | N23: =IF(J23=0,0, $C$27*(J23-1)*22) -> 0 | O23: =+K23+L23+M23+N23 -> 0 | P23: 0 | Q23: =+C23*P23 -> 0 | R23: =(+Q23*$C$26)+(S23*$C$26) -> 0 | S23: =+((P23/12)*2)*C23 -> 0 | T23: =IF(P23=0,0, $C$27*(P23-1)*22) -> 0 | U23: =+Q23+R23+S23+T23 -> 0 | V23: 0 | W23: =+C23*V23 -> 0 | X23: =(+W23*$C$26)+(Y23*$C$26) -> 0 | Y23: =+((V23/12)*2)*C23 -> 0 | Z23: =IF(V23=0,0, $C$27*(V23-1)*22) -> 0 | AA23: =+W23+X23+Y23+Z23 -> 0 | AB23: =+V23+P23+J23+D23 -> 0 | AC23: =+AA23+U23+O23+I23 -> 0
B24: Total | I24: =SUM(I20:I23) -> 0 | O24: =SUM(O20:O23) -> 0 | U24: =SUM(U20:U23) -> 0 | AA24: =SUM(AA20:AA23) -> 0 | AB24: =SUM(AB20:AB23) -> 0 | AC24: =SUM(AC20:AC23) -> 0
B26: Taxa de segurança Social | C26: 0.2375 | D26: =C20*C26 -> 0 | AB26: Custo total 36 Meses
B27: Subsídio refeição (dia) | C27: 6 | D27: =C27*22 -> 132

Sheet RH_EQUIPA
W3: SIM
W4: NÃO
B9: SACCT-Projetos de Investigação Científica e Desenvolvimento Tecnológico (IC&DT)
B12: Pessoal técnico do beneficiário da Universidade do Algarve
B14: Atenção: Nos termos do aviso do concurso o número máximo de FTEs/ ETIs imputável por ano, equivalente a uma pessoa dedicada ao projeto por 12 meses em full time (100%), é 11 (= 11 meses de trabalho). Exemplos: a) Um contrato em full time por 24 meses 100% dedicado ao projeto corresponde a uma afetação de 22 FTEs/ ETIs (24 meses x 11 / 12 = 22 FTEs/ ETIs); b) Um contrato em full time por 15 meses 100% dedicado ao projeto corresponde a uma afetação de 13,75 FTEs/ ETIs (15 meses x 11 / 12 = 13,75 FTEs/ ETIs); c) Um contrato em full time por 6 meses 100% dedicado ao projeto corresponde a uma afetação de 5,5 FTEs/ ETIs (6 meses x 11 / 12 = 5,5 FTEs/ ETIs). Perfis/ modalidades de contrato que podem ser incluídos como nova contratação: a) Investigador Doutorado DL57/2016 (afetação fixa de 27,50 FTEs/ ETIs por contrato; = 30 meses de contrato); b) Bolsa de Iniciação à Investigação (BII); c) Bolsa de Investigação - Licenciado (BI_L); d) Bolsa de Investigação - Mestre (BI_M); e) Bolsa de Investigação Pós-Doutoral (BIPD).
B16: N.º | C16: EQUIPA UALG | D16: Nova contratação? | E16: % afetação ao projeto | F16: N.º de FTEs/ ETIs
F17: =YEAR(RESUMO!E32) -> 2026 | G17: =F17+1 -> 2027 | H17: =G17+1 -> 2028 | I17: =H17+1 -> 2029 | J17: =I17+1 -> 2030 | K17: =J17+1 -> 2031 | L17: Total
F18: =IF(YEAR(RESUMO!E51)=F17,RESUMO!F51*0.916666666666667,"") -> 2.75 | G18: =+RESUMO!F52*11/12 -> 11 | H18: =+RESUMO!F53*11/12 -> 11 | I18: =IF(YEAR(RESUMO!E55)=I17,RESUMO!F55*11/12,"") -> 8.25 | J18: =IF(YEAR(RESUMO!F55)=J17,RESUMO!G55*11/12,"") | K18: =IF(YEAR(RESUMO!G55)=K17,RESUMO!H55*11/12,"")
B19: =IF(C19>0,1,"") -> 1 | C19: Ana Cristina Coelho | D19: NÃO | E19: 0.35 | F19: =IF($F$18="",0,$E19*$F$18) -> 0.9625 | G19: =+$E19*$G$18 -> 3.85 | H19: =+$E19*$H$18 -> 3.85 | I19: =IF($I$18="",0,$E19*$I$18) -> 2.8875 | L19: =SUM(F19:K19) -> 11.55
B20: =IF(C20>0,B19+1,"") -> 2 | C20: Ana Maria Costa | D20: NÃO | E20: 0.15 | F20: =IF($F$18="",0,$E20*$F$18) -> 0.4125 | G20: =+$E20*$G$18 -> 1.65 | H20: =+$E20*$H$18 -> 1.65 | I20: =IF($I$18="",0,$E20*$I$18) -> 1.2375 | L20: =SUM(F20:K20) -> 4.95
B21: =IF(C21>0,B20+1,"") -> 3 | C21: Cristina Veiga-Pires | D21: NÃO | E21: 0.15 | F21: =IF($F$18="",0,$E21*$F$18) -> 0.4125 | G21: =+$E21*$G$18 -> 1.65 | H21: =+$E21*$H$18 -> 1.65 | I21: =IF($I$18="",0,$E21*$I$18) -> 1.2375 | L21: =SUM(F21:K21) -> 4.95
B22: =IF(C22>0,B21+1,"") -> 4 | C22: Jorge Semião | D22: NÃO | E22: 0.05 | F22: =IF($F$18="",0,$E22*$F$18) -> 0.1375 | G22: =+$E22*$G$18 -> 0.55 | H22: =+$E22*$H$18 -> 0.55 | I22: =IF($I$18="",0,$E22*$I$18) -> 0.4125 | L22: =SUM(F22:K22) -> 1.65
B23: =IF(C23>0,B22+1,"") -> 5 | C23: Jânio Monteiro | D23: NÃO | E23: 0.05 | F23: =IF($F$18="",0,$E23*$F$18) -> 0.1375 | G23: =+$E23*$G$18 -> 0.55 | H23: =+$E23*$H$18 -> 0.55 | I23: =IF($I$18="",0,$E23*$I$18) -> 0.4125 | L23: =SUM(F23:K23) -> 1.65
B24: =IF(C24>0,B23+1,"") -> 6 | C24: Pedro cardoso | D24: NÃO | E24: 0.05 | F24: =IF($F$18="",0,$E24*$F$18) -> 0.1375 | G24: =+$E24*$G$18 -> 0.55 | H24: =+$E24*$H$18 -> 0.55 | I24: =IF($I$18="",0,$E24*$I$18) -> 0.4125 | L24: =SUM(F24:K24) -> 1.65
B25: =IF(C25>0,B24+1,"") -> 7 | C25: Roberto Lam | D25: NÃO | E25: 0.05 | F25: =IF($F$18="",0,$E25*$F$18) -> 0.1375 | G25: =+$E25*$G$18 -> 0.55 | H25: =+$E25*$H$18 -> 0.55 | I25: =IF($I$18="",0,$E25*$I$18) -> 0.4125 | L25: =SUM(F25:K25) -> 1.65
B26: =IF(C26>0,B25+1,"") -> 8 | C26: Cristiano Cabrita | D26: NÃO | E26: 0.05 | F26: =IF($F$18="",0,$E26*$F$18) -> 0.1375 | G26: =+$E26*$G$18 -> 0.55 | H26: =+$E26*$H$18 -> 0.55 | I26: =IF($I$18="",0,$E26*$I$18) -> 0.4125 | L26: =SUM(F26:K26) -> 1.65
B27: =IF(C27>0,B26+1,"") -> 9 | C27: Jaime Martins | D27: NÃO | E27: 0.05 | F27: =IF($F$18="",0,$E27*$F$18) -> 0.1375 | G27: =+$E27*$G$18 -> 0.55 | H27: =+$E27*$H$18 -> 0.55 | I27: =IF($I$18="",0,$E27*$I$18) -> 0.4125 | L27: =SUM(F27:K27) -> 1.65
B28: =IF(C28>0,B27+1,"") -> 10 | C28: Paulo Silva | D28: NÃO | E28: 0.15 | F28: =IF($F$18="",0,$E28*$F$18) -> 0.4125 | G28: =+$E28*$G$18 -> 1.65 | H28: =+$E28*$H$18 -> 1.65 | I28: =IF($I$18="",0,$E28*$I$18) -> 1.2375 | L28: =SUM(F28:K28) -> 4.95
B29: =IF(C29>0,B28+1,"") -> 11 | C29: João Rodrigues | D29: NÃO | E29: 0.02 | F29: =IF($F$18="",0,$E29*$F$18) -> 0.055 | G29: =+$E29*$G$18 -> 0.22 | H29: =+$E29*$H$18 -> 0.22 | I29: =IF($I$18="",0,$E29*$I$18) -> 0.165 | L29: =SUM(F29:K29) -> 0.66
B30: =IF(C30>0,B29+1,"") -> 12 | C30: Joana Lessa | D30: NÃO | E30: 0.2 | F30: =IF($F$18="",0,$E30*$F$18) -> 0.55 | G30: =+$E30*$G$18 -> 2.2 | H30: =+$E30*$H$18 -> 2.2 | I30: =IF($I$18="",0,$E30*$I$18) -> 1.65 | L30: =SUM(F30:K30) -> 6.6
B31: 13 | C31: José Moreira | D31: NÃO | E31: 0.15 | F31: =IF($F$18="",0,$E31*$F$18) -> 0.4125 | G31: =+$E31*$G$18 -> 1.65 | H31: =+$E31*$H$18 -> 1.65 | I31: =IF($I$18="",0,$E31*$I$18) -> 1.2375 | L31: =SUM(F31:K31) -> 4.95
B32: 14 | C32: Joel Guerreiro | D32: NÃO | E32: 0.1 | F32: =IF($F$18="",0,$E32*$F$18) -> 0.275 | G32: =+$E32*$G$18 -> 1.1 | H32: =+$E32*$H$18 -> 1.1 | I32: =IF($I$18="",0,$E32*$I$18) -> 0.825 | L32: =SUM(F32:K32) -> 3.3
C33: BOLSEIROS DE INVESTIGAÇÃO
B34: B1 | C34: =IF(RH_BOLSEIROS!$E$14="SIM",RH_BOLSEIROS!B20,"") -> Bolsas de Investigação (BI)- estudantes de doutoramento | D34: SIM | E34: =IF(C34="",0%,100%) -> 1 | F34: =11*RH_BOLSEIROS!D20/12 -> 0 | G34: =+RH_BOLSEIROS!H20*0.916666666666667 -> 11 | H34: =+RH_BOLSEIROS!L20*0.916666666666667 -> 11 | I34: =+RH_BOLSEIROS!P20*0.916666666666667 -> 5.5 | J34: =+RH_BOLSEIROS!T20*11/12 -> 0 | L34: =SUM(F34:K34) -> 27.5
B35: B2 | C35: =IF(RH_BOLSEIROS!$E$14="SIM",RH_BOLSEIROS!B21,"") -> Bolsas de Investigação (BI)- estudantes de doutoramento | D35: SIM | E35: =IF(C35="",0%,100%) -> 1 | F35: =11*RH_BOLSEIROS!D21/12 -> 0 | G35: =+RH_BOLSEIROS!H21*0.916666666666667 -> 11 | H35: =+RH_BOLSEIROS!L21*0.916666666666667 -> 11 | I35: =+RH_BOLSEIROS!P21*0.916666666666667 -> 5.5 | J35: =+RH_BOLSEIROS!T21*11/12 -> 0 | L35: =SUM(F35:K35) -> 27.5
B36: B3 | C36: =IF(RH_BOLSEIROS!$E$14="SIM",RH_BOLSEIROS!B22,"") -> Bolsas de investigação pós doutoral | D36: SIM | E36: =IF(C36="",0%,100%) -> 1 | F36: =11*RH_BOLSEIROS!D22/12 -> 0 | G36: =+RH_BOLSEIROS!H22*0.916666666666667 -> 11 | H36: =+RH_BOLSEIROS!L22*0.916666666666667 -> 11 | I36: =+RH_BOLSEIROS!P22*0.916666666666667 -> 5.5 | J36: =+RH_BOLSEIROS!T22*11/12 -> 0 | L36: =SUM(F36:K36) -> 27.5
B37: B4 | C37: =IF(RH_BOLSEIROS!$E$14="SIM",RH_BOLSEIROS!B23,"") -> Sem bolsa | D37: SIM | E37: 1 | F37: =11*RH_BOLSEIROS!D23/12 -> 0 | G37: =+RH_BOLSEIROS!H23*0.916666666666667 -> 0 | H37: =+RH_BOLSEIROS!L23*0.916666666666667 -> 0 | I37: =+RH_BOLSEIROS!P23*0.916666666666667 -> 0 | J37: =+RH_BOLSEIROS!T23*11/12 -> 0 | L37: =SUM(F37:K37) -> 0
C38: CONTRATOS DE INVESTIGAÇÃO
C39: =IF(RH_CONTRATOS!$E$14="SIM",RH_CONTRATOS!B20,"") | D39: SIM | E39: =IF(C39="",0%,100%) -> 0 | F39: =11*RH_CONTRATOS!D20/12 -> 0 | G39: =+RH_CONTRATOS!J20*0.916666666666667 -> 0 | H39: =+RH_CONTRATOS!P20*0.916666666666667 -> 0 | I39: =+RH_CONTRATOS!V20*0.916666666666667 -> 0 | L39: =SUM(F39:J39) -> 0
C40: =IF(RH_CONTRATOS!$E$14="SIM",RH_CONTRATOS!B21,"") | D40: SIM | E40: =IF(C40="",0%,100%) -> 0 | F40: =11*RH_CONTRATOS!D21/12 -> 0 | G40: =+RH_CONTRATOS!J21*0.916666666666667 -> 0 | H40: =+RH_CONTRATOS!P21*0.916666666666667 -> 0 | I40: =+RH_CONTRATOS!V21*0.916666666666667 -> 0 | L40: =SUM(F40:J40) -> 0

Sheet RH_ETI_Atividade
B11: DISTRIBUIÇÂO DA EQUIPA POR ATIVIDADES
D13: =YEAR(CRONOGRAMA!F13) -> 2026 | E13: =YEAR(CRONOGRAMA!G13) -> 2026 | F13: =YEAR(CRONOGRAMA!H13) -> 2026 | G13: =YEAR(CRONOGRAMA!I13) -> 2027 | H13: =YEAR(CRONOGRAMA!J13) -> 2027 | I13: =YEAR(CRONOGRAMA!K13) -> 2027 | J13: =YEAR(CRONOGRAMA!L13) -> 2027 | K13: =YEAR(CRONOGRAMA!M13) -> 2027 | ... AM13: =YEAR(CRONOGRAMA!AO13) -> 2029 | AN13: TOTAL | AO13: =YEAR(RESUMO!E32) -> 2026 | AP13: =AO13+1 -> 2027 | AQ13: =AP13+1 -> 2028 | AR13: =AQ13+1 -> 2029
B14: Membro da Equipa de Investigação | C14: ATIVIDADE | D14: =IF(RESUMO!$E$33>0,1,"") -> 1 | E14: =IF(RESUMO!$E$33>0,D14+1,"") -> 2 | F14: =IF(RESUMO!$E$33>0,E14+1,"") -> 3 | G14: =IF(RESUMO!$E$33>0,F14+1,"") -> 4 | H14: =IF(RESUMO!$E$33>0,G14+1,"") -> 5 | I14: =IF(RESUMO!$E$33>0,H14+1,"") -> 6 | J14: =IF(RESUMO!$E$33>0,I14+1,"") -> 7 | K14: =IF(RESUMO!$E$33>0,J14+1,"") -> 8 | L14: =IF(RESUMO!$E$33>0,K14+1,"") -> 9 | ... AM14: =IF(RESUMO!$E$33>0,AL14+1,"") -> 36 | AO14: 2024
B15: Ana Cristina Coelho | C15: A1 | D15: 0.65 | I15: 0.5 | L15: 0.5 | U15: 0.5 | AG15: 0.5 | AJ15: 0.5 | AM15: 0.5 | AN15: =SUM(D15:AM15) -> 3.65 | AO15: =SUMIF($D$13:$AM$13,$AO$13,D15:AM15) -> 0.65 | AP15: =SUMIF($D$13:$AM$13,$AP$13,D15:AM15) -> 1 | AQ15: =SUMIF($D$13:$AM$13,$AQ$13,D15:AM15) -> 0.5 | AR15: =SUMIF($D$13:$AM$13,$AR$13,D15:AM15) -> 1.5
B16: Ana Cristina Coelho | C16: A2 | G16: 0.5 | S16: 0.5 | Z16: 0.3 | AN16: =SUM(D16:AM16) -> 1.3 | AO16: =SUMIF($D$13:$AM$13,$AO$13,D16:AM16) -> 0 | AP16: =SUMIF($D$13:$AM$13,$AP$13,D16:AM16) -> 0.5 | AQ16: =SUMIF($D$13:$AM$13,$AQ$13,D16:AM16) -> 0.8 | AR16: =SUMIF($D$13:$AM$13,$AR$13,D16:AM16) -> 0
B17: Ana Cristina Coelho | C17: A3 | H17: 0.5 | T17: 0.5 | AA17: 0.5 | AN17: =SUM(D17:AM17) -> 1.5 | AO17: =SUMIF($D$13:$AM$13,$AO$13,D17:AM17) -> 0 | AP17: =SUMIF($D$13:$AM$13,$AP$13,D17:AM17) -> 0.5 | AQ17: =SUMIF($D$13:$AM$13,$AQ$13,D17:AM17) -> 1 | AR17: =SUMIF($D$13:$AM$13,$AR$13,D17:AM17) -> 0
B18: Ana Cristina Coelho | C18: A4 | I18: 0.5 | N18: 0.5 | W18: 0.5 | Y18: 0.5 | AN18: =SUM(D18:AM18) -> 2 | AO18: =SUMIF($D$13:$AM$13,$AO$13,D18:AM18) -> 0 | AP18: =SUMIF($D$13:$AM$13,$AP$13,D18:AM18) -> 1 | AQ18: =SUMIF($D$13:$AM$13,$AQ$13,D18:AM18) -> 1 | AR18: =SUMIF($D$13:$AM$13,$AR$13,D18:AM18) -> 0
B19: Ana Cristina Coelho | C19: A5 | Z19: 0.5 | AC19: 0.5 | AF19: 0.5 | AH19: 0.5 | AN19: =SUM(D19:AM19) -> 2 | AO19: =SUMIF($D$13:$AM$13,$AO$13,D19:AM19) -> 0 | AP19: =SUMIF($D$13:$AM$13,$AP$13,D19:AM19) -> 0 | AQ19: =SUMIF($D$13:$AM$13,$AQ$13,D19:AM19) -> 1 | AR19: =SUMIF($D$13:$AM$13,$AR$13,D19:AM19) -> 1
B20: Ana Cristina Coelho | C20: A6 | X20: 0.5 | AK20: 0.6 | AN20: =SUM(D20:AM20) -> 1.1 | AO20: =SUMIF($D$13:$AM$13,$AO$13,D20:AM20) -> 0 | AP20: =SUMIF($D$13:$AM$13,$AP$13,D20:AM20) -> 0 | AQ20: =SUMIF($D$13:$AM$13,$AQ$13,D20:AM20) -> 0.5 | AR20: =SUMIF($D$13:$AM$13,$AR$13,D20:AM20) -> 0.6
B21: Ana Maria Costa | C21: A1 | E21: 0.5 | AF21: 0.5 | AN21: =SUM(D21:AM21) -> 1 | AO21: =SUMIF($D$13:$AM$13,$AO$13,D21:AM21) -> 0.5 | AP21: =SUMIF($D$13:$AM$13,$AP$13,D21:AM21) -> 0 | AQ21: =SUMIF($D$13:$AM$13,$AQ$13,D21:AM21) -> 0 | AR21: =SUMIF($D$13:$AM$13,$AR$13,D21:AM21) -> 0.5
B22: Ana Maria Costa | C22: A4 | G22: 0.5 | Q22: 0.5 | S22: 0.5 | AE22: 0.5 | AN22: =SUM(D22:AM22) -> 2 | AO22: =SUMIF($D$13:$AM$13,$AO$13,D22:AM22) -> 0 | AP22: =SUMIF($D$13:$AM$13,$AP$13,D22:AM22) -> 1 | AQ22: =SUMIF($D$13:$AM$13,$AQ$13,D22:AM22) -> 0.5 | AR22: =SUMIF($D$13:$AM$13,$AR$13,D22:AM22) -> 0.5
B23: Ana Maria Costa | C23: A5 | X23: 0.5 | AG23: 0.5 | AN23: =SUM(D23:AM23) -> 1 | AO23: =SUMIF($D$13:$AM$13,$AO$13,D23:AM23) -> 0 | AP23: =SUMIF($D$13:$AM$13,$AP$13,D23:AM23) -> 0 | AQ23: =SUMIF($D$13:$AM$13,$AQ$13,D23:AM23) -> 0.5 | AR23: =SUMIF($D$13:$AM$13,$AR$13,D23:AM23) -> 0.5
B24: Ana Maria Costa | C24: A6 | V24: 0.5 | AK24: 0.45 | AN24: =SUM(D24:AM24) -> 0.95 | AO24: =SUMIF($D$13:$AM$13,$AO$13,D24:AM24) -> 0 | AP24: =SUMIF($D$13:$AM$13,$AP$13,D24:AM24) -> 0 | AQ24: =SUMIF($D$13:$AM$13,$AQ$13,D24:AM24) -> 0.5 | AR24: =SUMIF($D$13:$AM$13,$AR$13,D24:AM24) -> 0.45
B25: Cristina Veiga-Pires | C25: A1 | F25: 0.5 | W25: 0.5 | AN25: =SUM(D25:AM25) -> 1 | AO25: =SUMIF($D$13:$AM$13,$AO$13,D25:AM25) -> 0.5 | AP25: =SUMIF($D$13:$AM$13,$AP$13,D25:AM25) -> 0 | AQ25: =SUMIF($D$13:$AM$13,$AQ$13,D25:AM25) -> 0.5 | AR25: =SUMIF($D$13:$AM$13,$AR$13,D25:AM25) -> 0
B26: Cristina Veiga-Pires | C26: A3 | G26: 0.5 | Q26: 0.5 | S26: 0.5 | AE26: 0.5 | AN26: =SUM(D26:AM26) -> 2 | AO26: =SUMIF($D$13:$AM$13,$AO$13,D26:AM26) -> 0 | AP26: =SUMIF($D$13:$AM$13,$AP$13,D26:AM26) -> 1 | AQ26: =SUMIF($D$13:$AM$13,$AQ$13,D26:AM26) -> 0.5 | AR26: =SUMIF($D$13:$AM$13,$AR$13,D26:AM26) -> 0.5
B27: Cristina Veiga-Pires | C27: A5 | U27: 0.5 | AG27: 0.5 | AN27: =SUM(D27:AM27) -> 1 | AO27: =SUMIF($D$13:$AM$13,$AO$13,D27:AM27) -> 0 | AP27: =SUMIF($D$13:$AM$13,$AP$13,D27:AM27) -> 0 | AQ27: =SUMIF($D$13:$AM$13,$AQ$13,D27:AM27) -> 0.5 | AR27: =SUMIF($D$13:$AM$13,$AR$13,D27:AM27) -> 0.5
B28: Cristina Veiga-Pires | C28: A6 | V28: 0.5 | AM28: 0.45 | AN28: =SUM(D28:AM28) -> 0.95 | AO28: =SUMIF($D$13:$AM$13,$AO$13,D28:AM28) -> 0 | AP28: =SUMIF($D$13:$AM$13,$AP$13,D28:AM28) -> 0 | AQ28: =SUMIF($D$13:$AM$13,$AQ$13,D28:AM28) -> 0.5 | AR28: =SUMIF($D$13:$AM$13,$AR$13,D28:AM28) -> 0.45
B29: Joana Lessa | C29: A1 | K29: 0.6 | Y29: 0.5 | AN29: =SUM(D29:AM29) -> 1.1 | AO29: =SUMIF($D$13:$AM$13,$AO$13,D29:AM29) -> 0 | AP29: =SUMIF($D$13:$AM$13,$AP$13,D29:AM29) -> 0.6 | AQ29: =SUMIF($D$13:$AM$13,$AQ$13,D29:AM29) -> 0.5 | AR29: =SUMIF($D$13:$AM$13,$AR$13,D29:AM29) -> 0
B30: Joana Lessa | C30: A6 | T30: 1 | W30: 1 | AA30: 0.5 | AC30: 0.5 | AF30: 0.5 | AI30: 1 | AK30: 0.5 | AM30: 0.5 | AN30: =SUM(D30:AM30) -> 5.5 | AO30: =SUMIF($D$13:$AM$13,$AO$13,D30:AM30) -> 0 | AP30: =SUMIF($D$13:$AM$13,$AP$13,D30:AM30) -> 0 | AQ30: =SUMIF($D$13:$AM$13,$AQ$13,D30:AM30) -> 3 | AR30: =SUMIF($D$13:$AM$13,$AR$13,D30:AM30) -> 2.5
B31: Jorge Semião | C31: A2 | H31: 0.5 | T31: 0.5 | AN31: =SUM(D31:AM31) -> 1 | AO31: =SUMIF($D$13:$AM$13,$AO$13,D31:AM31) -> 0 | AP31: =SUMIF($D$13:$AM$13,$AP$13,D31:AM31) -> 0.5 | AQ31: =SUMIF($D$13:$AM$13,$AQ$13,D31:AM31) -> 0.5 | AR31: =SUMIF($D$13:$AM$13,$AR$13,D31:AM31) -> 0
B32: Jorge Semião | C32: A5 | AA32: 0.35 | AE32: 0.3 | AN32: =SUM(D32:AM32) -> 0.65 | AO32: =SUMIF($D$13:$AM$13,$AO$13,D32:AM32) -> 0 | AP32: =SUMIF($D$13:$AM$13,$AP$13,D32:AM32) -> 0 | AQ32: =SUMIF($D$13:$AM$13,$AQ$13,D32:AM32) -> 0.35 | AR32: =SUMIF($D$13:$AM$13,$AR$13,D32:AM32) -> 0.3
B33: Jânio Monteiro | C33: A3 | H33: 0.5 | T33: 0.5 | AN33: =SUM(D33:AM33) -> 1 | AO33: =SUMIF($D$13:$AM$13,$AO$13,D33:AM33) -> 0 | AP33: =SUMIF($D$13:$AM$13,$AP$13,D33:AM33) -> 0.5 | AQ33: =SUMIF($D$13:$AM$13,$AQ$13,D33:AM33) -> 0.5 | AR33: =SUMIF($D$13:$AM$13,$AR$13,D33:AM33) -> 0
B34: Jânio Monteiro | C34: A5 | AF34: 0.65 | AN34: =SUM(D34:AM34) -> 0.65 | AO34: =SUMIF($D$13:$AM$13,$AO$13,D34:AM34) -> 0 | AP34: =SUMIF($D$13:$AM$13,$AP$13,D34:AM34) -> 0 | AQ34: =SUMIF($D$13:$AM$13,$AQ$13,D34:AM34) -> 0 | AR34: =SUMIF($D$13:$AM$13,$AR$13,D34:AM34) -> 0.65
B35: Pedro cardoso | C35: A5 | X35: 0.65 | AB35: 0.5 | AI35: 0.5 | AN35: =SUM(D35:AM35) -> 1.65 | AO35: =SUMIF($D$13:$AM$13,$AO$13,D35:AM35) -> 0 | AP35: =SUMIF($D$13:$AM$13,$AP$13,D35:AM35) -> 0 | AQ35: =SUMIF($D$13:$AM$13,$AQ$13,D35:AM35) -> 1.15 | AR35: =SUMIF($D$13:$AM$13,$AR$13,D35:AM35) -> 0.5
B36: Roberto Lam | C36: A2 | J36: 0.5 | U36: 0.5 | AN36: =SUM(D36:AM36) -> 1 | AO36: =SUMIF($D$13:$AM$13,$AO$13,D36:AM36) -> 0 | AP36: =SUMIF($D$13:$AM$13,$AP$13,D36:AM36) -> 0.5 | AQ36: =SUMIF($D$13:$AM$13,$AQ$13,D36:AM36) -> 0.5 | AR36: =SUMIF($D$13:$AM$13,$AR$13,D36:AM36) -> 0
B37: Roberto Lam | C37: A5 | AC37: 0.65 | AN37: =SUM(D37:AM37) -> 0.65 | AO37: =SUMIF($D$13:$AM$13,$AO$13,D37:AM37) -> 0 | AP37: =SUMIF($D$13:$AM$13,$AP$13,D37:AM37) -> 0 | AQ37: =SUMIF($D$13:$AM$13,$AQ$13,D37:AM37) -> 0.65 | AR37: =SUMIF($D$13:$AM$13,$AR$13,D37:AM37) -> 0
B38: Cristiano Cabrita | C38: A2 | J38: 0.5 | U38: 0.5 | AN38: =SUM(D38:AM38) -> 1 | AO38: =SUMIF($D$13:$AM$13,$AO$13,D38:AM38) -> 0 | AP38: =SUMIF($D$13:$AM$13,$AP$13,D38:AM38) -> 0.5 | AQ38: =SUMIF($D$13:$AM$13,$AQ$13,D38:AM38) -> 0.5 | AR38: =SUMIF($D$13:$AM$13,$AR$13,D38:AM38) -> 0
B39: Cristiano Cabrita | C39: A5 | AC39: 0.65 | AN39: =SUM(D39:AM39) -> 0.65 | AO39: =SUMIF($D$13:$AM$13,$AO$13,D39:AM39) -> 0 | AP39: =SUMIF($D$13:$AM$13,$AP$13,D39:AM39) -> 0 | AQ39: =SUMIF($D$13:$AM$13,$AQ$13,D39:AM39) -> 0.65 | AR39: =SUMIF($D$13:$AM$13,$AR$13,D39:AM39) -> 0
B40: Jaime Martins | C40: A5 | T40: 0.5 | X40: 0.65 | AF40: 0.5 | AN40: =SUM(D40:AM40) -> 1.65 | AO40: =SUMIF($D$13:$AM$13,$AO$13,D40:AM40) -> 0 | AP40: =SUMIF($D$13:$AM$13,$AP$13,D40:AM40) -> 0 | AQ40: =SUMIF($D$13:$AM$13,$AQ$13,D40:AM40) -> 1.15 | AR40: =SUMIF($D$13:$AM$13,$AR$13,D40:AM40) -> 0.5
B41: Paulo Silva | C41: A2 | G41: 0.5 | M41: 0.5 | T41: 0.5 | AD41: 0.5 | AN41: =SUM(D41:AM41) -> 2 | AO41: =SUMIF($D$13:$AM$13,$AO$13,D41:AM41) -> 0 | AP41: =SUMIF($D$13:$AM$13,$AP$13,D41:AM41) -> 1 | AQ41: =SUMIF($D$13:$AM$13,$AQ$13,D41:AM41) -> 1 | AR41: =SUMIF($D$13:$AM$13,$AR$13,D41:AM41) -> 0
B42: Paulo Silva | C42: A3 | H42: 0.5 | O42: 0.5 | S42: 0.5 | AE42: 0.5 | AN42: =SUM(D42:AM42) -> 2 | AO42: =SUMIF($D$13:$AM$13,$AO$13,D42:AM42) -> 0 | AP42: =SUMIF($D$13:$AM$13,$AP$13,D42:AM42) -> 1 | AQ42: =SUMIF($D$13:$AM$13,$AQ$13,D42:AM42) -> 0.5 | AR42: =SUMIF($D$13:$AM$13,$AR$13,D42:AM42) -> 0.5
B43: Paulo Silva | C43: A5 | V43: 0.5 | AG43: 0.45 | AN43: =SUM(D43:AM43) -> 0.95 | AO43: =SUMIF($D$13:$AM$13,$AO$13,D43:AM43) -> 0 | AP43: =SUMIF($D$13:$AM$13,$AP$13,D43:AM43) -> 0 | AQ43: =SUMIF($D$13:$AM$13,$AQ$13,D43:AM43) -> 0.5 | AR43: =SUMIF($D$13:$AM$13,$AR$13,D43:AM43) -> 0.45
B44: José Moreira | C44: A4 | K44: 1 | V44: 0.5 | AN44: =SUM(D44:AM44) -> 1.5 | AO44: =SUMIF($D$13:$AM$13,$AO$13,D44:AM44) -> 0 | AP44: =SUMIF($D$13:$AM$13,$AP$13,D44:AM44) -> 1 | AQ44: =SUMIF($D$13:$AM$13,$AQ$13,D44:AM44) -> 0.5 | AR44: =SUMIF($D$13:$AM$13,$AR$13,D44:AM44) -> 0
B45: José Moreira | C45: A5 | T45: 1 | AE45: 0.5 | AN45: =SUM(D45:AM45) -> 1.5 | AO45: =SUMIF($D$13:$AM$13,$AO$13,D45:AM45) -> 0 | AP45: =SUMIF($D$13:$AM$13,$AP$13,D45:AM45) -> 0 | AQ45: =SUMIF($D$13:$AM$13,$AQ$13,D45:AM45) -> 1 | AR45: =SUMIF($D$13:$AM$13,$AR$13,D45:AM45) -> 0.5
B46: José Moreira | C46: A6 | X46: 1 | AJ46: 0.95 | AN46: =SUM(D46:AM46) -> 1.95 | AO46: =SUMIF($D$13:$AM$13,$AO$13,D46:AM46) -> 0 | AP46: =SUMIF($D$13:$AM$13,$AP$13,D46:AM46) -> 0 | AQ46: =SUMIF($D$13:$AM$13,$AQ$13,D46:AM46) -> 1 | AR46: =SUMIF($D$13:$AM$13,$AR$13,D46:AM46) -> 0.95
B47: João Rodrigues | C47: A5 | AB47: 0.3 | AG47: 0.36 | AN47: =SUM(D47:AM47) -> 0.66 | AO47: =SUMIF($D$13:$AM$13,$AO$13,D47:AM47) -> 0 | AP47: =SUMIF($D$13:$AM$13,$AP$13,D47:AM47) -> 0 | AQ47: =SUMIF($D$13:$AM$13,$AQ$13,D47:AM47) -> 0.3 | AR47: =SUMIF($D$13:$AM$13,$AR$13,D47:AM47) -> 0.36
B48: Joel Guerreiro | C48: A2 | J48: 1 | U48: 0.5 | AN48: =SUM(D48:AM48) -> 1.5 | AO48: =SUMIF($D$13:$AM$13,$AO$13,D48:AM48) -> 0 | AP48: =SUMIF($D$13:$AM$13,$AP$13,D48:AM48) -> 1 | AQ48: =SUMIF($D$13:$AM$13,$AQ$13,D48:AM48) -> 0.5 | AR48: =SUMIF($D$13:$AM$13,$AR$13,D48:AM48) -> 0
B49: Joel Guerreiro | C49: A5 | AC49: 1 | AG49: 0.8 | AN49: =SUM(D49:AM49) -> 1.8 | AO49: =SUMIF($D$13:$AM$13,$AO$13,D49:AM49) -> 0 | AP49: =SUMIF($D$13:$AM$13,$AP$13,D49:AM49) -> 0 | AQ49: =SUMIF($D$13:$AM$13,$AQ$13,D49:AM49) -> 1 | AR49: =SUMIF($D$13:$AM$13,$AR$13,D49:AM49) -> 0.8
B50: B1 | C50: A2 | G50: 1 | J50: 1 | M50: 1 | P50: 1 | S50: 1 | AB50: 1 | AN50: =SUM(D50:AM50) -> 6 | AO50: =SUMIF($D$13:$AM$13,$AO$13,D50:AM50) -> 0 | AP50: =SUMIF($D$13:$AM$13,$AP$13,D50:AM50) -> 4 | AQ50: =SUMIF($D$13:$AM$13,$AQ$13,D50:AM50) -> 2 | AR50: =SUMIF($D$13:$AM$13,$AR$13,D50:AM50) -> 0
B51: B1 | C51: A3 | H51: 1 | K51: 1 | L51: 1 | M51: 1 | Q51: 1 | T51: 1 | AA51: 1 | AC51: 1 | AN51: =SUM(D51:AM51) -> 8 | AO51: =SUMIF($D$13:$AM$13,$AO$13,D51:AM51) -> 0 | AP51: 5 | AQ51: 3 | AR51: =SUMIF($D$13:$AM$13,$AR$13,D51:AM51) -> 0
...

Sheet RH_ETI_QUADROS
B11: Identificação da Atividade por FTE | ORÇAMENTO UAlg | J11: (ESTES QUADROS SÃO DE PREENCHIMENTO AUTOMÁTICO)
B14: 94.0.0 OCS -Custo Unitário | D14: 4320
C16: FTE/ETI
B17: ATIVIDADE | C17: =RH_ETI_Atividade!AO13 -> 2026 | D17: =RH_ETI_Atividade!AP13 -> 2027 | E17: =RH_ETI_Atividade!AQ13 -> 2028 | F17: =RH_ETI_Atividade!AR13 -> 2029 | G17: TOTAL | H17: VALOR POR ATIVIDADE | I17: CLASSIFICAÇÃO
B18: =ATIVIDADES!C18 -> A1 | C18: =SUMIF(RH_ETI_Atividade!$C$15:$C$121,B18,RH_ETI_Atividade!$AO$15:$AO$121) -> 1.65 | D18: =SUMIF(RH_ETI_Atividade!$C$15:$C$121,B18,RH_ETI_Atividade!$AP$15:$AP$121) -> 1.6 | E18: =SUMIF(RH_ETI_Atividade!$C$15:$C$121,B18,RH_ETI_Atividade!$AQ$15:$AQ$121) -> 1.5 | F18: =SUMIF(RH_ETI_Atividade!$C$15:$C$121,B18,RH_ETI_Atividade!$AR$15:$AR$121) -> 2 | G18: =SUM(C18:F18) -> 6.75 | H18: =+G18*$D$14 -> 29160 | I18: =IF(ATIVIDADES!D18>0,VLOOKUP(B18,ATIVIDADES!C17:H28,6,FALSE),"") -> Gestão Projeto
B19: =ATIVIDADES!C19 -> A2 | C19: =SUMIF(RH_ETI_Atividade!$C$15:$C$121,B19,RH_ETI_Atividade!$AO$15:$AO$121) -> 0 | D19: =SUMIF(RH_ETI_Atividade!$C$15:$C$121,B19,RH_ETI_Atividade!$AP$15:$AP$121) -> 14 | E19: =SUMIF(RH_ETI_Atividade!$C$15:$C$121,B19,RH_ETI_Atividade!$AQ$15:$AQ$121) -> 12.8 | F19: =SUMIF(RH_ETI_Atividade!$C$15:$C$121,B19,RH_ETI_Atividade!$AR$15:$AR$121) -> 0 | G19: =SUM(C19:F19) -> 26.8 | H19: =+G19*$D$14 -> 115776 | I19: =IF(ATIVIDADES!D19>0,VLOOKUP(B19,ATIVIDADES!C18:H29,6,FALSE),"") -> Desenvolvimento Experimental
B20: =ATIVIDADES!C20 -> A3 | C20: =SUMIF(RH_ETI_Atividade!$C$15:$C$121,B20,RH_ETI_Atividade!$AO$15:$AO$121) -> 0 | D20: =SUMIF(RH_ETI_Atividade!$C$15:$C$121,B20,RH_ETI_Atividade!$AP$15:$AP$121) -> 15 | E20: =SUMIF(RH_ETI_Atividade!$C$15:$C$121,B20,RH_ETI_Atividade!$AQ$15:$AQ$121) -> 10.5 | F20: =SUMIF(RH_ETI_Atividade!$C$15:$C$121,B20,RH_ETI_Atividade!$AR$15:$AR$121) -> 1 | G20: =SUM(C20:F20) -> 26.5 | H20: =+G20*$D$14 -> 114480 | I20: =IF(ATIVIDADES!D20>0,VLOOKUP(B20,ATIVIDADES!C19:H30,6,FALSE),"") -> Desenvolvimento Experimental
B21: =ATIVIDADES!C21 -> A4 | C21: =SUMIF(RH_ETI_Atividade!$C$15:$C$121,B21,RH_ETI_Atividade!$AO$15:$AO$121) -> 0 | D21: =SUMIF(RH_ETI_Atividade!$C$15:$C$121,B21,RH_ETI_Atividade!$AP$15:$AP$121) -> 8 | E21: =SUMIF(RH_ETI_Atividade!$C$15:$C$121,B21,RH_ETI_Atividade!$AQ$15:$AQ$121) -> 5 | F21: =SUMIF(RH_ETI_Atividade!$C$15:$C$121,B21,RH_ETI_Atividade!$AR$15:$AR$121) -> 0.5 | G21: =SUM(C21:F21) -> 13.5 | H21: =+G21*$D$14 -> 58320 | I21: Fundamental
B22: =ATIVIDADES!C22 -> A5 | C22: =SUMIF(RH_ETI_Atividade!$C$15:$C$121,B22,RH_ETI_Atividade!$AO$15:$AO$121) -> 0 | D22: =SUMIF(RH_ETI_Atividade!$C$15:$C$121,B22,RH_ETI_Atividade!$AP$15:$AP$121) -> 0 | E22: =SUMIF(RH_ETI_Atividade!$C$15:$C$121,B22,RH_ETI_Atividade!$AQ$15:$AQ$121) -> 20.25 | F22: =SUMIF(RH_ETI_Atividade!$C$15:$C$121,B22,RH_ETI_Atividade!$AR$15:$AR$121) -> 14.06 | G22: =SUM(C22:F22) -> 34.31 | H22: =+G22*$D$14 -> 148219.2 | I22: =IF(ATIVIDADES!D22>0,VLOOKUP(B22,ATIVIDADES!C21:H32,6,FALSE),"") -> Desenvolvimento Experimental
B23: =ATIVIDADES!C23 -> A6 | C23: =SUMIF(RH_ETI_Atividade!$C$15:$C$121,B23,RH_ETI_Atividade!$AO$15:$AO$121) -> 0 | D23: =SUMIF(RH_ETI_Atividade!$C$15:$C$121,B23,RH_ETI_Atividade!$AP$15:$AP$121) -> 0 | E23: =SUMIF(RH_ETI_Atividade!$C$15:$C$121,B23,RH_ETI_Atividade!$AQ$15:$AQ$121) -> 13 | F23: =SUMIF(RH_ETI_Atividade!$C$15:$C$121,B23,RH_ETI_Atividade!$AR$15:$AR$121) -> 13.45 | G23: =SUM(C23:F23) -> 26.45 | H23: =+G23*$D$14 -> 114264 | I23: =IF(ATIVIDADES!D23>0,VLOOKUP(B23,ATIVIDADES!C22:H33,6,FALSE),"") -> Divulgação e Promoção
B24: =ATIVIDADES!C24 -> A7 | C24: =SUMIF(RH_ETI_Atividade!$C$15:$C$121,B24,RH_ETI_Atividade!$AO$15:$AO$121) -> 0 | D24: =SUMIF(RH_ETI_Atividade!$C$15:$C$121,B24,RH_ETI_Atividade!$AP$15:$AP$121) -> 0 | E24: =SUMIF(RH_ETI_Atividade!$C$15:$C$121,B24,RH_ETI_Atividade!$AQ$15:$AQ$121) -> 0 | F24: =SUMIF(RH_ETI_Atividade!$C$15:$C$121,B24,RH_ETI_Atividade!$AR$15:$AR$121) -> 0 | G24: =SUM(C24:F24) -> 0 | H24: =+G24*$D$14 -> 0 | I24: =IF(ATIVIDADES!D24>0,VLOOKUP(B24,ATIVIDADES!C23:H34,6,FALSE),"")
B25: =ATIVIDADES!C25 -> A8 | C25: =SUMIF(RH_ETI_Atividade!$C$15:$C$121,B25,RH_ETI_Atividade!$AO$15:$AO$121) -> 0 | D25: =SUMIF(RH_ETI_Atividade!$C$15:$C$121,B25,RH_ETI_Atividade!$AP$15:$AP$121) -> 0 | E25: =SUMIF(RH_ETI_Atividade!$C$15:$C$121,B25,RH_ETI_Atividade!$AQ$15:$AQ$121) -> 0 | F25: =SUMIF(RH_ETI_Atividade!$C$15:$C$121,B25,RH_ETI_Atividade!$AR$15:$AR$121) -> 0 | G25: =SUM(C25:F25) -> 0 | H25: =+G25*$D$14 -> 0 | I25: =IF(ATIVIDADES!D25>0,VLOOKUP(B25,ATIVIDADES!C24:H35,6,FALSE),"")
B26: =ATIVIDADES!C26 -> A9 | C26: =SUMIF(RH_ETI_Atividade!$C$15:$C$121,B26,RH_ETI_Atividade!$AO$15:$AO$121) -> 0 | D26: =SUMIF(RH_ETI_Atividade!$C$15:$C$121,B26,RH_ETI_Atividade!$AP$15:$AP$121) -> 0 | E26: =SUMIF(RH_ETI_Atividade!$C$15:$C$121,B26,RH_ETI_Atividade!$AQ$15:$AQ$121) -> 0 | F26: =SUMIF(RH_ETI_Atividade!$C$15:$C$121,B26,RH_ETI_Atividade!$AR$15:$AR$121) -> 0 | G26: =SUM(C26:F26) -> 0 | H26: =+G26*$D$14 -> 0 | I26: =IF(ATIVIDADES!D26>0,VLOOKUP(B26,ATIVIDADES!C25:H36,6,FALSE),"")
B27: =ATIVIDADES!C27 -> A10 | C27: =SUMIF(RH_ETI_Atividade!$C$15:$C$121,B27,RH_ETI_Atividade!$AO$15:$AO$121) -> 0 | D27: =SUMIF(RH_ETI_Atividade!$C$15:$C$121,B27,RH_ETI_Atividade!$AP$15:$AP$121) -> 0 | E27: =SUMIF(RH_ETI_Atividade!$C$15:$C$121,B27,RH_ETI_Atividade!$AQ$15:$AQ$121) -> 0 | F27: =SUMIF(RH_ETI_Atividade!$C$15:$C$121,B27,RH_ETI_Atividade!$AR$15:$AR$121) -> 0 | G27: =SUM(C27:F27) -> 0 | H27: =+G27*$D$14 -> 0 | I27: =IF(ATIVIDADES!D27>0,VLOOKUP(B27,ATIVIDADES!C26:H37,6,FALSE),"")
B28: =ATIVIDADES!C28 -> A11 | C28: =SUMIF(RH_ETI_Atividade!$C$15:$C$121,B28,RH_ETI_Atividade!$AO$15:$AO$121) -> 0 | D28: =SUMIF(RH_ETI_Atividade!$C$15:$C$121,B28,RH_ETI_Atividade!$AP$15:$AP$121) -> 0 | E28: =SUMIF(RH_ETI_Atividade!$C$15:$C$121,B28,RH_ETI_Atividade!$AQ$15:$AQ$121) -> 0 | F28: =SUMIF(RH_ETI_Atividade!$C$15:$C$121,B28,RH_ETI_Atividade!$AR$15:$AR$121) -> 0 | G28: =SUM(C28:F28) -> 0 | H28: =+G28*$D$14 -> 0 | I28: =IF(ATIVIDADES!D28>0,VLOOKUP(B28,ATIVIDADES!C27:H38,6,FALSE),"")
B29: TOTAL | C29: =SUM(C18:C28) -> 1.65 | D29: =SUM(D18:D28) -> 38.6 | E29: =SUM(E18:E28) -> 63.05 | F29: =SUM(F18:F28) -> 31.01 | G29: =SUM(G18:G28) -> 134.31 | H29: =SUM(H18:H28) -> 580219.2
B33: ATIVIDADE | C33: =RH_ETI_Atividade!AO13 -> 2026 | D33: =RH_ETI_Atividade!AP13 -> 2027 | E33: =RH_ETI_Atividade!AQ13 -> 2028 | F33: =RH_ETI_Atividade!AR13 -> 2029 | G33: TOTAL
B34: A1 | C34: =+$D$14*C18 -> 7128 | D34: =+$D$14*D18 -> 6912 | E34: =+E18*$D$14 -> 6480 | F34: =+F18*$D$14 -> 8640 | G34: =SUM(C34:F34) -> 29160
B35: A2 | C35: =+$D$14*C19 -> 0 | D35: =+$D$14*D19 -> 60480 | E35: =+E19*$D$14 -> 55296 | F35: =+F19*$D$14 -> 0 | G35: =SUM(C35:F35) -> 115776
B36: A3 | C36: =+$D$14*C20 -> 0 | D36: =+$D$14*D20 -> 64800 | E36: =+E20*$D$14 -> 45360 | F36: =+F20*$D$14 -> 4320 | G36: =SUM(C36:F36) -> 114480
B37: A4 | C37: =+$D$14*C21 -> 0 | D37: =+$D$14*D21 -> 34560 | E37: =+E21*$D$14 -> 21600 | F37: =+F21*$D$14 -> 2160 | G37: =SUM(C37:F37) -> 58320
B38: A5 | C38: =+$D$14*C22 -> 0 | D38: =+$D$14*D22 -> 0 | E38: =+E22*$D$14 -> 87480 | F38: =+F22*$D$14 -> 60739.2 | G38: =SUM(C38:F38) -> 148219.2
B39: A6 | C39: =+$D$14*C23 -> 0 | D39: =+$D$14*D23 -> 0 | E39: =+E23*$D$14 -> 56160 | F39: =+F23*$D$14 -> 58104 | G39: =SUM(C39:F39) -> 114264
B40: A7 | C40: =+$D$14*C24 -> 0 | D40: =+$D$14*D24 -> 0 | E40: =+E24*$D$14 -> 0 | F40: =+F24*$D$14 -> 0 | G40: =SUM(C40:F40) -> 0
B41: A8 | C41: =+$D$14*C25 -> 0 | D41: =+$D$14*D25 -> 0 | E41: =+E25*$D$14 -> 0 | F41: =+F25*$D$14 -> 0 | G41: =SUM(C41:F41) -> 0
B42: A9 | C42: =+$D$14*C26 -> 0 | D42: =+$D$14*D26 -> 0 | E42: =+E26*$D$14 -> 0 | F42: =+F26*$D$14 -> 0 | G42: =SUM(C42:F42) -> 0
B43: A10 | C43: =+$D$14*C27 -> 0 | D43: =+$D$14*D27 -> 0 | E43: =+E27*$D$14 -> 0 | F43: =+F27*$D$14 -> 0 | G43: =SUM(C43:F43) -> 0
B44: A11 | C44: =+$D$14*C28 -> 0 | D44: =+$D$14*D28 -> 0 | E44: =+E28*$D$14 -> 0 | F44: =+F28*$D$14 -> 0 | G44: =SUM(C44:F44) -> 0
B45: TOTAL | C45: =SUM(C34:C44) -> 7128 | D45: =SUM(D34:D44) -> 166752 | E45: =SUM(E34:E44) -> 272376 | F45: =SUM(F34:F44) -> 133963.2 | G45: =SUM(G34:G44) -> 580219.2
B47: Autofinanciamento | C47: =+C45*0.25 -> 1782 | D47: =+D45*0.25 -> 41688 | E47: =+E45*0.25 -> 68094 | F47: =+F45*0.25 -> 33490.8 | G47: =+G45*0.25 -> 145054.8
B49: Identificação da EQUIPA por FTE | ORÇAMENTO
C52: FTE/ETI
B53: EQUIPA | C53: A1 | D53: A2 | E53: A3 | F53: A4 | G53: A5 | H53: A6 | I53: A7 | J53: A8 | K53: A9 | L53: A10 | M53: A11 | N53: TOTAL | O53: FOLHA RH_EQUIPA
